Workbook

Sheet Cover
A1: Bouvet ASA (BOUV.OL) – valuation model
A2: Generated by Equity Research Engine on 2026-09-23
A4: Share price (NOK) | B4: =Inputs!$B$5 -> 47.4
A5: DCF fair value per share (NOK) | B5: =DCF!B21 -> 73.995407
A6: Probability-weighted scenario value (NOK) | B6: =Scenarios!$I$8 -> 76.102639
A7: Target price (NOK) | B7: =DCF!B30 -> 77
A8: Upside to target price | B8: =DCF!B31 -> 0.62447257
A9: Expected total return | B9: =DCF!B32 -> 0.68776371
A10: Rating | B10: =DCF!B33 -> BUY
A11: Model checks | B11: =Checks!$B$17 -> ALL OK
A12: WACC | B12: =WACC!$B$17 -> 0.083
A13: Terminal growth | B13: =Inputs!$B$11 -> 0.02
A14: EV/EBITDA (LTM) | B14: =Peers!E22 -> 9.514316
A15: Peer median EV/EBITDA | B15: =Peers!F22 -> 8.9872663
A18: Legend
A19: Blue text = hard-coded input (edit these)
A20: Black text = formula
A21: Green text = link to another sheet
A22: Yellow fill = key assumption
A24: Sheets: Inputs -> Historicals -> Forecast -> WACC -> DCF -> Peers -> Football field
A25: Lease treatment: operating. Sources: Company reports, Yahoo Finance, Equity Research Engine estimates

Sheet Inputs
A1: Bouvet ASA – model inputs
A2: All figures in NOKm unless stated. Blue = input, black = formula, green = link.
A4: Market data | B4: Value | C4: Source / note
A5: Share price (NOK) | B5: 47.4 | C5: Yahoo Finance close
A6: FX: NOK per NOK | B6: 1 | C6: 1.0 when the company reports in its listing currency
A7: Shares outstanding (m) | B7: 102.36305 | C7: Yahoo Finance
A8: Net debt | B8: -159.733 | C8: Balance sheet 30.06.2026 (ex leases)
A9: Minority interest | B9: 0 | C9: Balance sheet 30.06.2026
A10: Tax rate | B10: 0.22 | C10: config
A11: Terminal growth | B11: 0.02 | C11: Config
A12: Risk-free rate | B12: 0.038 | C12: Config
A13: Equity risk premium | B13: 0.05 | C13: Config
A14: Beta (adjusted) | B14: 0.6 | C14: Yahoo Finance (5y monthly); regression vs OSEBX rejected (R2=0.01 < 0.10), Blume-adjusted
A15: Size premium | B15: 0.015 | C15: size premium 1.50% (market cap USD 0.5bn)
A16: Cost of debt (pre-tax) | B16: 0.058 | C16: risk-free + 200bp
... A29: SELL threshold (total return) | B29: -0.1 | C29: Config
A32: Forecast drivers | B32: 2026E | C32: 2027E | D32: 2028E | E32: 2029E | F32: 2030E | G32: 2031E
A33: Revenue growth | B33: 0.0147 | C33: 0.0776 | D33: 0.0632 | E33: 0.0488 | F33: 0.0344 | G33: 0.02
A34: EBITDA margin | B34: 0.13456663 | C34: 0.13494102 | D34: 0.1353154 | E34: 0.13568979 | F34: 0.13606417 | G34: 0.13643856
A35: D&A % of revenue | B35: 0.012982145 | C35: 0.012982145 | D35: 0.012982145 | E35: 0.012982145 | F35: 0.012982145 | G35: 0.012982145
A36: Capex % of revenue | B36: 0.010221778 | C36: 0.010221778 | D36: 0.010221778 | E36: 0.010221778 | F36: 0.010221778 | G36: 0.010221778
A37: Net working capital % of revenue | B37: -0.069648947 | C37: -0.069648947 | D37: -0.069648947 | E37: -0.069648947 | F37: -0.069648947 | G37: -0.069648947
A39: Notes: Revenue growth anchored on consensus (2 analysts), fading linearly to 2.0% terminal growth. EBITDA margin held near the 3-year average of 13.6%. Net working capital held at -7.0% of revenue (3-year average from the balance sheet).
A40: Lease treatment: operating (lease rate 4.50%). Growth anchor: consensus (2 analysts).

Sheet Historicals
A1: Bouvet ASA – historical financials (NOKm)
A2: Source: company reports via Yahoo Finance; lease adjustments per methodology.
A4: NOKm | B4: 2022A | C4: 2023A | D4: 2024A | E4: 2025A
A5: Revenue | B5: 3085.47 | C5: 3525.761 | D5: 3921.399 | E5: 3912.343
A6: Growth | C6: =IF(B5=0,"",C5/B5-1) -> 0.1426982 | D6: =IF(C5=0,"",D5/C5-1) -> 0.11221351 | E6: =IF(D5=0,"",E5/D5-1) -> -0.0023093799
A7: EBITDA (reported) | B7: 486.743 | C7: 524.084 | D7: 635.282 | E7: 597.216
A8: Lease cost (rent) | B8: 51.3956 | C8: 61.5614 | D8: 70.837107 | E8: 72.209912
A9: EBITDA | B9: =B7-B8 -> 435.3474 | C9: =C7-C8 -> 462.5226 | D9: =D7-D8 -> 564.44489 | E9: =E7-E8 -> 525.00609
A10: EBITDA margin | B10: =IF(B5=0,"",B9/B5) -> 0.14109598 | C10: =IF(C5=0,"",C9/C5) -> 0.13118376 | D10: =IF(D5=0,"",D9/D5) -> 0.14393967 | E10: =IF(E5=0,"",E9/E5) -> 0.13419224
A11: D&A (reported) | B11: 79.046 | C11: 96.918 | D11: 120.252 | E11: 99.193
A12: Right-of-use depreciation | B12: 46.026 | C12: 54.563 | D12: 56.513 | E12: 57.412
A13: D&A | B13: =MAX(B11-B12,0) -> 33.02 | C13: =MAX(C11-C12,0) -> 42.355 | D13: =MAX(D11-D12,0) -> 63.739 | E13: =MAX(E11-E12,0) -> 41.781
A14: EBIT | B14: =B9-B13 -> 402.3274 | C14: =C9-C13 -> 420.1676 | D14: =D9-D13 -> 500.70589 | E14: =E9-E13 -> 483.22509
A15: EBIT margin | B15: =IF(B5=0,"",B14/B5) -> 0.1303942 | C15: =IF(C5=0,"",C14/C5) -> 0.11917075 | D15: =IF(D5=0,"",D14/D5) -> 0.12768553 | E15: =IF(E5=0,"",E14/E5) -> 0.12351297
A16: Tax rate (effective, used) | B16: 0.21115254 | C16: 0.22256691 | D16: 0.21935638 | E16: 0.24097439
A17: NOPAT | B17: =B14*(1-B16) -> 317.37495 | C17: =C14*(1-C16) -> 326.6522 | D17: =D14*(1-D16) -> 390.87286 | E17: =E14*(1-E16) -> 366.78022
A18: Capex | B18: -41.018 | C18: -51.581 | D18: -36.501 | E18: -26.32
A19: Change in NWC | B19: -106.325 | C19: 69.18 | D19: 326.619 | E19: -106.299
A20: Unlevered FCF | B20: =B17+B13+B18+B19 -> 203.05195 | C20: =C17+C13+C18+C19 -> 386.6062 | D20: =D17+D13+D18+D19 -> 744.72986 | E20: =E17+E13+E18+E19 -> 275.94222
A21: FCF margin | B21: =IF(B5=0,"",B20/B5) -> 0.065809082 | C21: =IF(C5=0,"",C20/C5) -> 0.10965184 | D21: =IF(D5=0,"",D20/D5) -> 0.18991433 | E21: =IF(E5=0,"",E20/E5) -> 0.070531193
A22: Net income | B22: 315.708 | C22: 325.419 | D22: 383.442 | E22: 358.673
A23: Diluted EPS | B23: 3.03 | C23: 3.13 | D23: 3.69 | E23: 3.46
A24: Cash | B24: 367.093 | C24: 398.074 | D24: 743.794 | E24: 579.884
A25: Total debt (incl. leases) | B25: 228.963 | C25: 320.867 | D25: 315.76 | E25: 341.925
A26: Lease liabilities | B26: 228.963 | C26: 320.867 | D26: 315.76 | E26: 341.925
A27: Net debt (model basis) | B27: -367.093 | C27: -398.074 | D27: -743.794 | E27: -579.884
A28: Net debt / EBITDA | B28: =IF(B9<=0,"n.m.",B27/B9) -> -0.84321854 | C28: =IF(C9<=0,"n.m.",C27/C9) -> -0.86065848 | D28: =IF(D9<=0,"n.m.",D27/D9) -> -1.3177442 | E28: =IF(E9<=0,"n.m.",E27/E9) -> -1.1045281
A29: Interest expense (ex leases) | B29: 1.3424 | C29: 1.7496 | D29: 9.3398925 | E29: 10.681088

Sheet Forecast
A1: Bouvet ASA – forecast (NOKm)
A2: Formulas reference the Inputs sheet; last actual year is linked from Historicals.
A4: NOKm | B4: 2025A | C4: 2026E | D4: 2027E | E4: 2028E | F4: 2029E | G4: 2030E | H4: 2031E | I4: Terminal
A5: Revenue growth | C5: =Inputs!B33 -> 0.0147 | D5: =Inputs!C33 -> 0.0776 | E5: =Inputs!D33 -> 0.0632 | F5: =Inputs!E33 -> 0.0488 | G5: =Inputs!F33 -> 0.0344 | H5: =Inputs!G33 -> 0.02 | I5: =Inputs!$B$11 -> 0.02
A6: Revenue | B6: =Historicals!E5 -> 3912.343 | C6: =B6*(1+C5) -> 3969.8544 | D6: =C6*(1+D5) -> 4277.9151 | E6: =D6*(1+E5) -> 4548.2794 | F6: =E6*(1+F5) -> 4770.2354 | G6: =F6*(1+G5) -> 4934.3315 | H6: =G6*(1+H5) -> 5033.0181 | I6: =H6*(1+I5) -> 5133.6785
A7: EBITDA margin | B7: =B8/B6 -> 0.13419224 | C7: =Inputs!B34 -> 0.13456663 | D7: =Inputs!C34 -> 0.13494102 | E7: =Inputs!D34 -> 0.1353154 | F7: =Inputs!E34 -> 0.13568979 | G7: =Inputs!F34 -> 0.13606417 | H7: =Inputs!G34 -> 0.13643856 | I7: =H7 -> 0.13643856
A8: EBITDA | B8: =Historicals!E9 -> 525.00609 | C8: =C6*C7 -> 534.20994 | D8: =D6*D7 -> 577.26622 | E8: =E6*E7 -> 615.45226 | F8: =F6*F7 -> 647.27224 | G8: =G6*G7 -> 671.38575 | H8: =H6*H7 -> 686.69775 | I8: =I6*I7 -> 700.43171
A9: D&A % of revenue | C9: =Inputs!B35 -> 0.012982145 | D9: =Inputs!C35 -> 0.012982145 | E9: =Inputs!D35 -> 0.012982145 | F9: =Inputs!E35 -> 0.012982145 | G9: =Inputs!F35 -> 0.012982145 | H9: =Inputs!G35 -> 0.012982145 | I9: =H9 -> 0.012982145
A10: D&A | B10: =Historicals!E13 -> 41.781 | C10: =C6*C9 -> 51.537227 | D10: =D6*D9 -> 55.536516 | E10: =E6*E9 -> 59.046424 | F10: =F6*F9 -> 61.927889 | G10: =G6*G9 -> 64.058209 | H10: =H6*H9 -> 65.339373 | I10: =I6*I9 -> 66.64616
A11: EBIT | B11: =Historicals!E14 -> 483.22509 | C11: =C8-C10 -> 482.67271 | D11: =D8-D10 -> 521.7297 | E11: =E8-E10 -> 556.40583 | F11: =F8-F10 -> 585.34435 | G11: =G8-G10 -> 607.32754 | H11: =H8-H10 -> 621.35838 | I11: =I8-I10 -> 633.78555
A12: EBIT margin | C12: =C11/C6 -> 0.12158449 | D12: =D11/D6 -> 0.12195887 | E12: =E11/E6 -> 0.12233326 | F12: =F11/F6 -> 0.12270764 | G12: =G11/G6 -> 0.12308203 | H12: =H11/H6 -> 0.12345642 | I12: =I11/I6 -> 0.12345642
A13: Tax | C13: =-MAX(C11,0)*Inputs!$B$10 -> -106.188 | D13: =-MAX(D11,0)*Inputs!$B$10 -> -114.78053 | E13: =-MAX(E11,0)*Inputs!$B$10 -> -122.40928 | F13: =-MAX(F11,0)*Inputs!$B$10 -> -128.77576 | G13: =-MAX(G11,0)*Inputs!$B$10 -> -133.61206 | H13: =-MAX(H11,0)*Inputs!$B$10 -> -136.69884 | I13: =-MAX(I11,0)*Inputs!$B$10 -> -139.43282
A14: NOPAT | B14: =Historicals!E17 -> 366.78022 | C14: =C11+C13 -> 376.48471 | D14: =D11+D13 -> 406.94917 | E14: =E11+E13 -> 433.99655 | F14: =F11+F13 -> 456.56859 | G14: =G11+G13 -> 473.71548 | H14: =H11+H13 -> 484.65954 | I14: =I11+I13 -> 494.35273
A15: Capex % of revenue | C15: =Inputs!B36 -> 0.010221778 | D15: =Inputs!C36 -> 0.010221778 | E15: =Inputs!D36 -> 0.010221778 | F15: =Inputs!E36 -> 0.010221778 | G15: =Inputs!F36 -> 0.010221778 | H15: =Inputs!G36 -> 0.010221778 | I15: =H15 -> 0.010221778
A16: Capex | B16: =Historicals!E18 -> -26.32 | C16: =-C6*C15 -> -40.57897 | D16: =-D6*D15 -> -43.727898 | E16: =-E6*E15 -> -46.491501 | F16: =-F6*F15 -> -48.760287 | G16: =-G6*G15 -> -50.437641 | H16: =-H6*H15 -> -51.446393 | I16: =-I6*I15 -> -52.475321
A17: Net working capital % of revenue | C17: =Inputs!B37 -> -0.069648947 | D17: =Inputs!C37 -> -0.069648947 | E17: =Inputs!D37 -> -0.069648947 | F17: =Inputs!E37 -> -0.069648947 | G17: =Inputs!F37 -> -0.069648947 | H17: =Inputs!G37 -> -0.069648947 | I17: =H17 -> -0.069648947
A18: Change in NWC | B18: =Historicals!E19 -> -106.299 | C18: =-C17*(C6-B6) -> 4.0056114 | D18: =-D17*(D6-C6) -> 21.456104 | E18: =-E17*(E6-D6) -> 18.830584 | F18: =-F17*(F6-E6) -> 15.459004 | G18: =-G17*(G6-F6) -> 11.42912 | H18: =-H17*(H6-G6) -> 6.8734199 | I18: =-I17*(I6-H6) -> 7.0108883
A19: Unlevered FCF | B19: =Historicals!E20 -> 275.94222 | C19: =C14+C10+C16+C18 -> 391.44858 | D19: =D14+D10+D16+D18 -> 440.21389 | E19: =E14+E10+E16+E18 -> 465.38206 | F19: =F14+F10+F16+F18 -> 485.1952 | G19: =G14+G10+G16+G18 -> 498.76517 | H19: =H14+H10+H16+H18 -> 505.42594 | I19: =I14+I10+I16+I18 -> 515.53445
A20: FCF margin | C20: =C19/C6 -> 0.098605273 | D20: =D19/D6 -> 0.10290384 | E20: =E19/E6 -> 0.10232046 | F20: =F19/F6 -> 0.10171305 | G20: =G19/G6 -> 0.1010806 | H20: =H19/H6 -> 0.10042204 | I20: =I19/I6 -> 0.10042204

Sheet WACC
A1: Cost of capital
A2: CAPM cost of equity, after-tax cost of debt, market-value weights.
A4: Component | B4: Value
A5: Risk-free rate | B5: =Inputs!$B$12 -> 0.038
A6: Beta (adjusted) | B6: =Inputs!$B$14 -> 0.6 | C6: Yahoo Finance (5y monthly); regression vs OSEBX rejected (R2=0.01 < 0.10), Blume-adjusted
A7: Equity risk premium | B7: =Inputs!$B$13 -> 0.05
A8: Size premium | B8: =Inputs!$B$15 -> 0.015
A9: Cost of equity | B9: =B5+B6*B7+B8 -> 0.083
A10: Cost of debt (pre-tax) | B10: =Inputs!$B$16 -> 0.058
A11: Tax rate | B11: =Inputs!$B$10 -> 0.22
A12: Cost of debt (after tax) | B12: =B10*(1-B11) -> 0.04524
A13: Equity value (market cap) | B13: =(Inputs!$B$5*Inputs!$B$6)*Inputs!$B$7 -> 4852.0087
A14: Debt value | B14: =Inputs!$B$17 -> 0
A15: Weight of equity | B15: =B13/(B13+B14) -> 1
A16: Weight of debt | B16: =B14/(B13+B14) -> 0
A17: WACC | B17: =B15*B9+B16*B12 -> 0.083
A19: Cross-check: bottom-up beta from the peer group (Hamada, tax at the corporate rate)
A20: Median unlevered peer beta | B20: 0.67472609
A21: Relevered at the target's D/E of 0.00 | B21: 0.67472609
A22: Blume-adjusted (compare with B6) | B22: 0.78206648
A23: Peers with a usable beta | B23: 8

Sheet DCF
A1: Bouvet ASA – DCF valuation (NOKm)
A2: Unlevered FCF discounted at WACC; Gordon growth terminal value.
A4: Year | B4: 2026E | C4: 2027E | D4: 2028E | E4: 2029E | F4: 2030E | G4: 2031E
A5: Unlevered FCF | B5: =Forecast!C19 -> 391.44858 | C5: =Forecast!D19 -> 440.21389 | D5: =Forecast!E19 -> 465.38206 | E5: =Forecast!F19 -> 485.1952 | F5: =Forecast!G19 -> 498.76517 | G5: =Forecast!H19 -> 505.42594
A6: Discount period (years from valuation date) | B6: =IF(Inputs!$B$18=1,(1+Inputs!$B$20)/2,1)-Inputs!$B$19 -> 0.27173169 | C6: =2-Inputs!$B$19-0.5*Inputs!$B$18 -> 1.2717317 | D6: =3-Inputs!$B$19-0.5*Inputs!$B$18 -> 2.2717317 | E6: =4-Inputs!$B$19-0.5*Inputs!$B$18 -> 3.2717317 | F6: =5-Inputs!$B$19-0.5*Inputs!$B$18 -> 4.2717317 | G6: =6-Inputs!$B$19-0.5*Inputs!$B$18 -> 5.2717317
A7: Discount factor | B7: =1/(1+WACC!$B$17)^B6 -> 0.97856652 | C7: =1/(1+WACC!$B$17)^C6 -> 0.90357019 | D7: =1/(1+WACC!$B$17)^D6 -> 0.8343215 | E7: =1/(1+WACC!$B$17)^E6 -> 0.77037997 | F7: =1/(1+WACC!$B$17)^F6 -> 0.71133884 | G7: =1/(1+WACC!$B$17)^G6 -> 0.65682257
A8: PV of FCF (year 1: after the balance-sheet date) | B8: =B5*(1-Inputs!$B$20)*B7 -> 193.23347 | C8: =C5*C7 -> 397.76415 | D8: =D5*D7 -> 388.27826 | E8: =E5*E7 -> 373.78466 | F8: =F5*F7 -> 354.79104 | G8: =G5*G7 -> 331.97516
A10: Sum of PV of FCF | B10: =SUM(B8:G8) -> 2039.8267
A11: Terminal growth | B11: =Inputs!$B$11 -> 0.02
A12: WACC | B12: =WACC!$B$17 -> 0.083
A13: Terminal cash flow (year N+1) | B13: =IF(Inputs!$B$21=1,Forecast!$H$14*(1+B11)*(1-B11/Inputs!$B$22),$G$5*(1+B11)) -> 515.53445
A14: Terminal value | B14: =B13/(B12-B11) -> 8183.0866
A15: PV of terminal value | B15: =B14/(1+B12)^(6-Inputs!$B$19) -> 5374.836
A16: Enterprise value | B16: =B10+B15 -> 7414.6627
A17: Less: net debt | B17: =-Inputs!$B$8 -> 159.733
A18: Less: minority interest | B18: =-Inputs!$B$9 -> 0
A19: Equity value | B19: =B16+B17+B18 -> 7574.3957
A20: Shares outstanding (m) | B20: =Inputs!$B$7 -> 102.36305
A21: Fair value per share, DCF (NOK) | B21: =B19/B20/Inputs!$B$6 -> 73.995407
A22: Current share price (NOK) | B22: =Inputs!$B$5 -> 47.4
A23: Upside / (downside) to fair value | B23: =B21/B22-1 -> 0.56108453
A24: Terminal value as % of EV | B24: =B15/B16 -> 0.72489285
A25: Implied exit EV/EBITDA | B25: =B14/Forecast!H8 -> 11.916577
A26: Fair value used for the target price | B26: =Inputs!$B$26*B21+(1-Inputs!$B$26)*Inputs!$B$27 -> 73.995407
A27: Cost of equity | B27: =WACC!$B$9 -> 0.083
A28: Expected dividend per share (NOK) | B28: =IF(Inputs!$B$24>0,Inputs!$B$23,0) -> 3
A29: Target price before rounding | B29: =IF(B26<=0,0,B26*(1+B27)^(Inputs!$B$24/12)-B28) -> 77.137026
A30: Target price (NOK) | B30: =IF(Inputs!$B$25>0,MROUND(B29,Inputs!$B$25),B29) -> 77
A31: Upside to target price | B31: =B30/B22-1 -> 0.62447257
A32: Expected total return (incl. dividend) | B32: =(B30+B28)/B22-1 -> 0.68776371
A33: Rating | B33: =IF(B26<=0,"NOT RATED",IF(B32>=Inputs!$B$28,"BUY",IF(B32<=Inputs!$B$29,"SELL","HOLD"))) -> BUY
A36: Sensitivity: value per share (rows = terminal growth, columns = WACC)
A37: g \ WACC | B37: =WACC!$B$17+(-3)*0.005 -> 0.068 | C37: =WACC!$B$17+(-2)*0.005 -> 0.073 | D37: =WACC!$B$17+(-1)*0.005 -> 0.078 | E37: =WACC!$B$17+(0)*0.005 -> 0.083 | F37: =WACC!$B$17+(1)*0.005 -> 0.088 | G37: =WACC!$B$17+(2)*0.005 -> 0.093 | H37: =WACC!$B$17+(3)*0.005 -> 0.098
A38: =Inputs!$B$11+(-3)*0.0025 -> 0.0125 | B38: =IF(B$37<=$A38,"n.m.",(SUMPRODUCT($B$5:$G$5,(1+B$37)^(-DCF!$B$6:$G$6))-$B$5*Inputs!$B$20*(1+B$37)^(-DCF!$B$6)+IF(Inputs!$B$21=1,Forecast!$H$14*(1+$A38)*(1-$A38/Inputs!$B$22),$G$5*(1+$A38))/(B$37-$A38)/(1+B$37)^(6-Inputs!$B$19)-Inputs!$B$8-Inputs!$B$9)/Inputs!$B$7/Inputs!$B$6) -> 85.996363 | C38: =IF(C$37<=$A38,"n.m.",(SUMPRODUCT($B$5:$G$5,(1+C$37)^(-DCF!$B$6:$G$6))-$B$5*Inputs!$B$20*(1+C$37)^(-DCF!$B$6)+IF(Inputs!$B$21=1,Forecast!$H$14*(1+$A38)*(1-$A38/Inputs!$B$22),$G$5*(1+$A38))/(C$37-$A38)/(1+C$37)^(6-Inputs!$B$19)-Inputs!$B$8-Inputs!$B$9)/Inputs!$B$7/Inputs!$B$6) -> 79.030142 | D38: =IF(D$37<=$A38,"n.m.",(SUMPRODUCT($B$5:$G$5,(1+D$37)^(-DCF!$B$6:$G$6))-$B$5*Inputs!$B$20*(1+D$37)^(-DCF!$B$6)+IF(Inputs!$B$21=1,Forecast!$H$14*(1+$A38)*(1-$A38/Inputs!$B$22),$G$5*(1+$A38))/(D$37-$A38)/(1+D$37)^(6-Inputs!$B$19)-Inputs!$B$8-Inputs!$B$9)/Inputs!$B$7/Inputs!$B$6) -> 73.128345 | E38: =IF(E$37<=$A38,"n.m.",(SUMPRODUCT($B$5:$G$5,(1+E$37)^(-DCF!$B$6:$G$6))-$B$5*Inputs!$B$20*(1+E$37)^(-DCF!$B$6)+IF(Inputs!$B$21=1,Forecast!$H$14*(1+$A38)*(1-$A38/Inputs!$B$22),$G$5*(1+$A38))/(E$37-$A38)/(1+E$37)^(6-Inputs!$B$19)-Inputs!$B$8-Inputs!$B$9)/Inputs!$B$7/Inputs!$B$6) -> 68.064482 | F38: =IF(F$37<=$A38,"n.m.",(SUMPRODUCT($B$5:$G$5,(1+F$37)^(-DCF!$B$6:$G$6))-$B$5*Inputs!$B$20*(1+F$37)^(-DCF!$B$6)+IF(Inputs!$B$21=1,Forecast!$H$14*(1+$A38)*(1-$A38/Inputs!$B$22),$G$5*(1+$A38))/(F$37-$A38)/(1+F$37)^(6-Inputs!$B$19)-Inputs!$B$8-Inputs!$B$9)/Inputs!$B$7/Inputs!$B$6) -> 63.672062 | G38: =IF(G$37<=$A38,"n.m.",(SUMPRODUCT($B$5:$G$5,(1+G$37)^(-DCF!$B$6:$G$6))-$B$5*Inputs!$B$20*(1+G$37)^(-DCF!$B$6)+IF(Inputs!$B$21=1,Forecast!$H$14*(1+$A38)*(1-$A38/Inputs!$B$22),$G$5*(1+$A38))/(G$37-$A38)/(1+G$37)^(6-Inputs!$B$19)-Inputs!$B$8-Inputs!$B$9)/Inputs!$B$7/Inputs!$B$6) -> 59.825958 | H38: =IF(H$37<=$A38,"n.m.",(SUMPRODUCT($B$5:$G$5,(1+H$37)^(-DCF!$B$6:$G$6))-$B$5*Inputs!$B$20*(1+H$37)^(-DCF!$B$6)+IF(Inputs!$B$21=1,Forecast!$H$14*(1+$A38)*(1-$A38/Inputs!$B$22),$G$5*(1+$A38))/(H$37-$A38)/(1+H$37)^(6-Inputs!$B$19)-Inputs!$B$8-Inputs!$B$9)/Inputs!$B$7/Inputs!$B$6) -> 56.430313
A39: =Inputs!$B$11+(-2)*0.0025 -> 0.015 | B39: =IF(B$37<=$A39,"n.m.",(SUMPRODUCT($B$5:$G$5,(1+B$37)^(-DCF!$B$6:$G$6))-$B$5*Inputs!$B$20*(1+B$37)^(-DCF!$B$6)+IF(Inputs!$B$21=1,Forecast!$H$14*(1+$A39)*(1-$A39/Inputs!$B$22),$G$5*(1+$A39))/(B$37-$A39)/(1+B$37)^(6-Inputs!$B$19)-Inputs!$B$8-Inputs!$B$9)/Inputs!$B$7/Inputs!$B$6) -> 89.164739 | C39: =IF(C$37<=$A39,"n.m.",(SUMPRODUCT($B$5:$G$5,(1+C$37)^(-DCF!$B$6:$G$6))-$B$5*Inputs!$B$20*(1+C$37)^(-DCF!$B$6)+IF(Inputs!$B$21=1,Forecast!$H$14*(1+$A39)*(1-$A39/Inputs!$B$22),$G$5*(1+$A39))/(C$37-$A39)/(1+C$37)^(6-Inputs!$B$19)-Inputs!$B$8-Inputs!$B$9)/Inputs!$B$7/Inputs!$B$6) -> 81.633639 | D39: =IF(D$37<=$A39,"n.m.",(SUMPRODUCT($B$5:$G$5,(1+D$37)^(-DCF!$B$6:$G$6))-$B$5*Inputs!$B$20*(1+D$37)^(-DCF!$B$6)+IF(Inputs!$B$21=1,Forecast!$H$14*(1+$A39)*(1-$A39/Inputs!$B$22),$G$5*(1+$A39))/(D$37-$A39)/(1+D$37)^(6-Inputs!$B$19)-Inputs!$B$8-Inputs!$B$9)/Inputs!$B$7/Inputs!$B$6) -> 75.298715 | E39: =IF(E$37<=$A39,"n.m.",(SUMPRODUCT($B$5:$G$5,(1+E$37)^(-DCF!$B$6:$G$6))-$B$5*Inputs!$B$20*(1+E$37)^(-DCF!$B$6)+IF(Inputs!$B$21=1,Forecast!$H$14*(1+$A39)*(1-$A39/Inputs!$B$22),$G$5*(1+$A39))/(E$37-$A39)/(1+E$37)^(6-Inputs!$B$19)-Inputs!$B$8-Inputs!$B$9)/Inputs!$B$7/Inputs!$B$6) -> 69.896091 | F39: =IF(F$37<=$A39,"n.m.",(SUMPRODUCT($B$5:$G$5,(1+F$37)^(-DCF!$B$6:$G$6))-$B$5*Inputs!$B$20*(1+F$37)^(-DCF!$B$6)+IF(Inputs!$B$21=1,Forecast!$H$14*(1+$A39)*(1-$A39/Inputs!$B$22),$G$5*(1+$A39))/(F$37-$A39)/(1+F$37)^(6-Inputs!$B$19)-Inputs!$B$8-Inputs!$B$9)/Inputs!$B$7/Inputs!$B$6) -> 65.234187 | G39: =IF(G$37<=$A39,"n.m.",(SUMPRODUCT($B$5:$G$5,(1+G$37)^(-DCF!$B$6:$G$6))-$B$5*Inputs!$B$20*(1+G$37)^(-DCF!$B$6)+IF(Inputs!$B$21=1,Forecast!$H$14*(1+$A39)*(1-$A39/Inputs!$B$22),$G$5*(1+$A39))/(G$37-$A39)/(1+G$37)^(6-Inputs!$B$19)-Inputs!$B$8-Inputs!$B$9)/Inputs!$B$7/Inputs!$B$6) -> 61.170545 | H39: =IF(H$37<=$A39,"n.m.",(SUMPRODUCT($B$5:$G$5,(1+H$37)^(-DCF!$B$6:$G$6))-$B$5*Inputs!$B$20*(1+H$37)^(-DCF!$B$6)+IF(Inputs!$B$21=1,Forecast!$H$14*(1+$A39)*(1-$A39/Inputs!$B$22),$G$5*(1+$A39))/(H$37-$A39)/(1+H$37)^(6-Inputs!$B$19)-Inputs!$B$8-Inputs!$B$9)/Inputs!$B$7/Inputs!$B$6) -> 57.597036
A40: =Inputs!$B$11+(-1)*0.0025 -> 0.0175 | B40: =IF(B$37<=$A40,"n.m.",(SUMPRODUCT($B$5:$G$5,(1+B$37)^(-DCF!$B$6:$G$6))-$B$5*Inputs!$B$20*(1+B$37)^(-DCF!$B$6)+IF(Inputs!$B$21=1,Forecast!$H$14*(1+$A40)*(1-$A40/Inputs!$B$22),$G$5*(1+$A40))/(B$37-$A40)/(1+B$37)^(6-Inputs!$B$19)-Inputs!$B$8-Inputs!$B$9)/Inputs!$B$7/Inputs!$B$6) -> 92.646816 | C40: =IF(C$37<=$A40,"n.m.",(SUMPRODUCT($B$5:$G$5,(1+C$37)^(-DCF!$B$6:$G$6))-$B$5*Inputs!$B$20*(1+C$37)^(-DCF!$B$6)+IF(Inputs!$B$21=1,Forecast!$H$14*(1+$A40)*(1-$A40/Inputs!$B$22),$G$5*(1+$A40))/(C$37-$A40)/(1+C$37)^(6-Inputs!$B$19)-Inputs!$B$8-Inputs!$B$9)/Inputs!$B$7/Inputs!$B$6) -> 84.471686 | D40: =IF(D$37<=$A40,"n.m.",(SUMPRODUCT($B$5:$G$5,(1+D$37)^(-DCF!$B$6:$G$6))-$B$5*Inputs!$B$20*(1+D$37)^(-DCF!$B$6)+IF(Inputs!$B$21=1,Forecast!$H$14*(1+$A40)*(1-$A40/Inputs!$B$22),$G$5*(1+$A40))/(D$37-$A40)/(1+D$37)^(6-Inputs!$B$19)-Inputs!$B$8-Inputs!$B$9)/Inputs!$B$7/Inputs!$B$6) -> 77.648455 | E40: =IF(E$37<=$A40,"n.m.",(SUMPRODUCT($B$5:$G$5,(1+E$37)^(-DCF!$B$6:$G$6))-$B$5*Inputs!$B$20*(1+E$37)^(-DCF!$B$6)+IF(Inputs!$B$21=1,Forecast!$H$14*(1+$A40)*(1-$A40/Inputs!$B$22),$G$5*(1+$A40))/(E$37-$A40)/(1+E$37)^(6-Inputs!$B$19)-Inputs!$B$8-Inputs!$B$9)/Inputs!$B$7/Inputs!$B$6) -> 71.867518 | F40: =IF(F$37<=$A40,"n.m.",(SUMPRODUCT($B$5:$G$5,(1+F$37)^(-DCF!$B$6:$G$6))-$B$5*Inputs!$B$20*(1+F$37)^(-DCF!$B$6)+IF(Inputs!$B$21=1,Forecast!$H$14*(1+$A40)*(1-$A40/Inputs!$B$22),$G$5*(1+$A40))/(F$37-$A40)/(1+F$37)^(6-Inputs!$B$19)-Inputs!$B$8-Inputs!$B$9)/Inputs!$B$7/Inputs!$B$6) -> 66.9071 | G40: =IF(G$37<=$A40,"n.m.",(SUMPRODUCT($B$5:$G$5,(1+G$37)^(-DCF!$B$6:$G$6))-$B$5*Inputs!$B$20*(1+G$37)^(-DCF!$B$6)+IF(Inputs!$B$21=1,Forecast!$H$14*(1+$A40)*(1-$A40/Inputs!$B$22),$G$5*(1+$A40))/(G$37-$A40)/(1+G$37)^(6-Inputs!$B$19)-Inputs!$B$8-Inputs!$B$9)/Inputs!$B$7/Inputs!$B$6) -> 62.604177 | H40: =IF(H$37<=$A40,"n.m.",(SUMPRODUCT($B$5:$G$5,(1+H$37)^(-DCF!$B$6:$G$6))-$B$5*Inputs!$B$20*(1+H$37)^(-DCF!$B$6)+IF(Inputs!$B$21=1,Forecast!$H$14*(1+$A40)*(1-$A40/Inputs!$B$22),$G$5*(1+$A40))/(H$37-$A40)/(1+H$37)^(6-Inputs!$B$19)-Inputs!$B$8-Inputs!$B$9)/Inputs!$B$7/Inputs!$B$6) -> 58.836226
A41: =Inputs!$B$11+(0)*0.0025 -> 0.02 | B41: =IF(B$37<=$A41,"n.m.",(SUMPRODUCT($B$5:$G$5,(1+B$37)^(-DCF!$B$6:$G$6))-$B$5*Inputs!$B$20*(1+B$37)^(-DCF!$B$6)+IF(Inputs!$B$21=1,Forecast!$H$14*(1+$A41)*(1-$A41/Inputs!$B$22),$G$5*(1+$A41))/(B$37-$A41)/(1+B$37)^(6-Inputs!$B$19)-Inputs!$B$8-Inputs!$B$9)/Inputs!$B$7/Inputs!$B$6) -> 96.491609 | C41: =IF(C$37<=$A41,"n.m.",(SUMPRODUCT($B$5:$G$5,(1+C$37)^(-DCF!$B$6:$G$6))-$B$5*Inputs!$B$20*(1+C$37)^(-DCF!$B$6)+IF(Inputs!$B$21=1,Forecast!$H$14*(1+$A41)*(1-$A41/Inputs!$B$22),$G$5*(1+$A41))/(C$37-$A41)/(1+C$37)^(6-Inputs!$B$19)-Inputs!$B$8-Inputs!$B$9)/Inputs!$B$7/Inputs!$B$6) -> 87.577473 | D41: =IF(D$37<=$A41,"n.m.",(SUMPRODUCT($B$5:$G$5,(1+D$37)^(-DCF!$B$6:$G$6))-$B$5*Inputs!$B$20*(1+D$37)^(-DCF!$B$6)+IF(Inputs!$B$21=1,Forecast!$H$14*(1+$A41)*(1-$A41/Inputs!$B$22),$G$5*(1+$A41))/(D$37-$A41)/(1+D$37)^(6-Inputs!$B$19)-Inputs!$B$8-Inputs!$B$9)/Inputs!$B$7/Inputs!$B$6) -> 80.200759 | E41: =IF(E$37<=$A41,"n.m.",(SUMPRODUCT($B$5:$G$5,(1+E$37)^(-DCF!$B$6:$G$6))-$B$5*Inputs!$B$20*(1+E$37)^(-DCF!$B$6)+IF(Inputs!$B$21=1,Forecast!$H$14*(1+$A41)*(1-$A41/Inputs!$B$22),$G$5*(1+$A41))/(E$37-$A41)/(1+E$37)^(6-Inputs!$B$19)-Inputs!$B$8-Inputs!$B$9)/Inputs!$B$7/Inputs!$B$6) -> 73.995407 | F41: =IF(F$37<=$A41,"n.m.",(SUMPRODUCT($B$5:$G$5,(1+F$37)^(-DCF!$B$6:$G$6))-$B$5*Inputs!$B$20*(1+F$37)^(-DCF!$B$6)+IF(Inputs!$B$21=1,Forecast!$H$14*(1+$A41)*(1-$A41/Inputs!$B$22),$G$5*(1+$A41))/(F$37-$A41)/(1+F$37)^(6-Inputs!$B$19)-Inputs!$B$8-Inputs!$B$9)/Inputs!$B$7/Inputs!$B$6) -> 68.703022 | G41: =IF(G$37<=$A41,"n.m.",(SUMPRODUCT($B$5:$G$5,(1+G$37)^(-DCF!$B$6:$G$6))-$B$5*Inputs!$B$20*(1+G$37)^(-DCF!$B$6)+IF(Inputs!$B$21=1,Forecast!$H$14*(1+$A41)*(1-$A41/Inputs!$B$22),$G$5*(1+$A41))/(G$37-$A41)/(1+G$37)^(6-Inputs!$B$19)-Inputs!$B$8-Inputs!$B$9)/Inputs!$B$7/Inputs!$B$6) -> 64.136004 | H41: =IF(H$37<=$A41,"n.m.",(SUMPRODUCT($B$5:$G$5,(1+H$37)^(-DCF!$B$6:$G$6))-$B$5*Inputs!$B$20*(1+H$37)^(-DCF!$B$6)+IF(Inputs!$B$21=1,Forecast!$H$14*(1+$A41)*(1-$A41/Inputs!$B$22),$G$5*(1+$A41))/(H$37-$A41)/(1+H$37)^(6-Inputs!$B$19)-Inputs!$B$8-Inputs!$B$9)/Inputs!$B$7/Inputs!$B$6) -> 60.154852
A42: =Inputs!$B$11+(1)*0.0025 -> 0.0225 | B42: =IF(B$37<=$A42,"n.m.",(SUMPRODUCT($B$5:$G$5,(1+B$37)^(-DCF!$B$6:$G$6))-$B$5*Inputs!$B$20*(1+B$37)^(-DCF!$B$6)+IF(Inputs!$B$21=1,Forecast!$H$14*(1+$A42)*(1-$A42/Inputs!$B$22),$G$5*(1+$A42))/(B$37-$A42)/(1+B$37)^(6-Inputs!$B$19)-Inputs!$B$8-Inputs!$B$9)/Inputs!$B$7/Inputs!$B$6) -> 100.75891 | C42: =IF(C$37<=$A42,"n.m.",(SUMPRODUCT($B$5:$G$5,(1+C$37)^(-DCF!$B$6:$G$6))-$B$5*Inputs!$B$20*(1+C$37)^(-DCF!$B$6)+IF(Inputs!$B$21=1,Forecast!$H$14*(1+$A42)*(1-$A42/Inputs!$B$22),$G$5*(1+$A42))/(C$37-$A42)/(1+C$37)^(6-Inputs!$B$19)-Inputs!$B$8-Inputs!$B$9)/Inputs!$B$7/Inputs!$B$6) -> 90.990763 | D42: =IF(D$37<=$A42,"n.m.",(SUMPRODUCT($B$5:$G$5,(1+D$37)^(-DCF!$B$6:$G$6))-$B$5*Inputs!$B$20*(1+D$37)^(-DCF!$B$6)+IF(Inputs!$B$21=1,Forecast!$H$14*(1+$A42)*(1-$A42/Inputs!$B$22),$G$5*(1+$A42))/(D$37-$A42)/(1+D$37)^(6-Inputs!$B$19)-Inputs!$B$8-Inputs!$B$9)/Inputs!$B$7/Inputs!$B$6) -> 82.983 | E42: =IF(E$37<=$A42,"n.m.",(SUMPRODUCT($B$5:$G$5,(1+E$37)^(-DCF!$B$6:$G$6))-$B$5*Inputs!$B$20*(1+E$37)^(-DCF!$B$6)+IF(Inputs!$B$21=1,Forecast!$H$14*(1+$A42)*(1-$A42/Inputs!$B$22),$G$5*(1+$A42))/(E$37-$A42)/(1+E$37)^(6-Inputs!$B$19)-Inputs!$B$8-Inputs!$B$9)/Inputs!$B$7/Inputs!$B$6) -> 76.299155 | F42: =IF(F$37<=$A42,"n.m.",(SUMPRODUCT($B$5:$G$5,(1+F$37)^(-DCF!$B$6:$G$6))-$B$5*Inputs!$B$20*(1+F$37)^(-DCF!$B$6)+IF(Inputs!$B$21=1,Forecast!$H$14*(1+$A42)*(1-$A42/Inputs!$B$22),$G$5*(1+$A42))/(F$37-$A42)/(1+F$37)^(6-Inputs!$B$19)-Inputs!$B$8-Inputs!$B$9)/Inputs!$B$7/Inputs!$B$6) -> 70.636038 | G42: =IF(G$37<=$A42,"n.m.",(SUMPRODUCT($B$5:$G$5,(1+G$37)^(-DCF!$B$6:$G$6))-$B$5*Inputs!$B$20*(1+G$37)^(-DCF!$B$6)+IF(Inputs!$B$21=1,Forecast!$H$14*(1+$A42)*(1-$A42/Inputs!$B$22),$G$5*(1+$A42))/(G$37-$A42)/(1+G$37)^(6-Inputs!$B$19)-Inputs!$B$8-Inputs!$B$9)/Inputs!$B$7/Inputs!$B$6) -> 65.77647 | H42: =IF(H$37<=$A42,"n.m.",(SUMPRODUCT($B$5:$G$5,(1+H$37)^(-DCF!$B$6:$G$6))-$B$5*Inputs!$B$20*(1+H$37)^(-DCF!$B$6)+IF(Inputs!$B$21=1,Forecast!$H$14*(1+$A42)*(1-$A42/Inputs!$B$22),$G$5*(1+$A42))/(H$37-$A42)/(1+H$37)^(6-Inputs!$B$19)-Inputs!$B$8-Inputs!$B$9)/Inputs!$B$7/Inputs!$B$6) -> 61.560804
A43: =Inputs!$B$11+(2)*0.0025 -> 0.025 | B43: =IF(B$37<=$A43,"n.m.",(SUMPRODUCT($B$5:$G$5,(1+B$37)^(-DCF!$B$6:$G$6))-$B$5*Inputs!$B$20*(1+B$37)^(-DCF!$B$6)+IF(Inputs!$B$21=1,Forecast!$H$14*(1+$A43)*(1-$A43/Inputs!$B$22),$G$5*(1+$A43))/(B$37-$A43)/(1+B$37)^(6-Inputs!$B$19)-Inputs!$B$8-Inputs!$B$9)/Inputs!$B$7/Inputs!$B$6) -> 105.5224 | C43: =IF(C$37<=$A43,"n.m.",(SUMPRODUCT($B$5:$G$5,(1+C$37)^(-DCF!$B$6:$G$6))-$B$5*Inputs!$B$20*(1+C$37)^(-DCF!$B$6)+IF(Inputs!$B$21=1,Forecast!$H$14*(1+$A43)*(1-$A43/Inputs!$B$22),$G$5*(1+$A43))/(C$37-$A43)/(1+C$37)^(6-Inputs!$B$19)-Inputs!$B$8-Inputs!$B$9)/Inputs!$B$7/Inputs!$B$6) -> 94.759605 | D43: =IF(D$37<=$A43,"n.m.",(SUMPRODUCT($B$5:$G$5,(1+D$37)^(-DCF!$B$6:$G$6))-$B$5*Inputs!$B$20*(1+D$37)^(-DCF!$B$6)+IF(Inputs!$B$21=1,Forecast!$H$14*(1+$A43)*(1-$A43/Inputs!$B$22),$G$5*(1+$A43))/(D$37-$A43)/(1+D$37)^(6-Inputs!$B$19)-Inputs!$B$8-Inputs!$B$9)/Inputs!$B$7/Inputs!$B$6) -> 86.027716 | E43: =IF(E$37<=$A43,"n.m.",(SUMPRODUCT($B$5:$G$5,(1+E$37)^(-DCF!$B$6:$G$6))-$B$5*Inputs!$B$20*(1+E$37)^(-DCF!$B$6)+IF(Inputs!$B$21=1,Forecast!$H$14*(1+$A43)*(1-$A43/Inputs!$B$22),$G$5*(1+$A43))/(E$37-$A43)/(1+E$37)^(6-Inputs!$B$19)-Inputs!$B$8-Inputs!$B$9)/Inputs!$B$7/Inputs!$B$6) -> 78.801501 | F43: =IF(F$37<=$A43,"n.m.",(SUMPRODUCT($B$5:$G$5,(1+F$37)^(-DCF!$B$6:$G$6))-$B$5*Inputs!$B$20*(1+F$37)^(-DCF!$B$6)+IF(Inputs!$B$21=1,Forecast!$H$14*(1+$A43)*(1-$A43/Inputs!$B$22),$G$5*(1+$A43))/(F$37-$A43)/(1+F$37)^(6-Inputs!$B$19)-Inputs!$B$8-Inputs!$B$9)/Inputs!$B$7/Inputs!$B$6) -> 72.722467 | G43: =IF(G$37<=$A43,"n.m.",(SUMPRODUCT($B$5:$G$5,(1+G$37)^(-DCF!$B$6:$G$6))-$B$5*Inputs!$B$20*(1+G$37)^(-DCF!$B$6)+IF(Inputs!$B$21=1,Forecast!$H$14*(1+$A43)*(1-$A43/Inputs!$B$22),$G$5*(1+$A43))/(G$37-$A43)/(1+G$37)^(6-Inputs!$B$19)-Inputs!$B$8-Inputs!$B$9)/Inputs!$B$7/Inputs!$B$6) -> 67.537559 | H43: =IF(H$37<=$A43,"n.m.",(SUMPRODUCT($B$5:$G$5,(1+H$37)^(-DCF!$B$6:$G$6))-$B$5*Inputs!$B$20*(1+H$37)^(-DCF!$B$6)+IF(Inputs!$B$21=1,Forecast!$H$14*(1+$A43)*(1-$A43/Inputs!$B$22),$G$5*(1+$A43))/(H$37-$A43)/(1+H$37)^(6-Inputs!$B$19)-Inputs!$B$8-Inputs!$B$9)/Inputs!$B$7/Inputs!$B$6) -> 63.063054
A44: =Inputs!$B$11+(3)*0.0025 -> 0.0275 | B44: =IF(B$37<=$A44,"n.m.",(SUMPRODUCT($B$5:$G$5,(1+B$37)^(-DCF!$B$6:$G$6))-$B$5*Inputs!$B$20*(1+B$37)^(-DCF!$B$6)+IF(Inputs!$B$21=1,Forecast!$H$14*(1+$A44)*(1-$A44/Inputs!$B$22),$G$5*(1+$A44))/(B$37-$A44)/(1+B$37)^(6-Inputs!$B$19)-Inputs!$B$8-Inputs!$B$9)/Inputs!$B$7/Inputs!$B$6) -> 110.87398 | C44: =IF(C$37<=$A44,"n.m.",(SUMPRODUCT($B$5:$G$5,(1+C$37)^(-DCF!$B$6:$G$6))-$B$5*Inputs!$B$20*(1+C$37)^(-DCF!$B$6)+IF(Inputs!$B$21=1,Forecast!$H$14*(1+$A44)*(1-$A44/Inputs!$B$22),$G$5*(1+$A44))/(C$37-$A44)/(1+C$37)^(6-Inputs!$B$19)-Inputs!$B$8-Inputs!$B$9)/Inputs!$B$7/Inputs!$B$6) -> 98.942605 | D44: =IF(D$37<=$A44,"n.m.",(SUMPRODUCT($B$5:$G$5,(1+D$37)^(-DCF!$B$6:$G$6))-$B$5*Inputs!$B$20*(1+D$37)^(-DCF!$B$6)+IF(Inputs!$B$21=1,Forecast!$H$14*(1+$A44)*(1-$A44/Inputs!$B$22),$G$5*(1+$A44))/(D$37-$A44)/(1+D$37)^(6-Inputs!$B$19)-Inputs!$B$8-Inputs!$B$9)/Inputs!$B$7/Inputs!$B$6) -> 89.37389 | E44: =IF(E$37<=$A44,"n.m.",(SUMPRODUCT($B$5:$G$5,(1+E$37)^(-DCF!$B$6:$G$6))-$B$5*Inputs!$B$20*(1+E$37)^(-DCF!$B$6)+IF(Inputs!$B$21=1,Forecast!$H$14*(1+$A44)*(1-$A44/Inputs!$B$22),$G$5*(1+$A44))/(E$37-$A44)/(1+E$37)^(6-Inputs!$B$19)-Inputs!$B$8-Inputs!$B$9)/Inputs!$B$7/Inputs!$B$6) -> 81.529284 | F44: =IF(F$37<=$A44,"n.m.",(SUMPRODUCT($B$5:$G$5,(1+F$37)^(-DCF!$B$6:$G$6))-$B$5*Inputs!$B$20*(1+F$37)^(-DCF!$B$6)+IF(Inputs!$B$21=1,Forecast!$H$14*(1+$A44)*(1-$A44/Inputs!$B$22),$G$5*(1+$A44))/(F$37-$A44)/(1+F$37)^(6-Inputs!$B$19)-Inputs!$B$8-Inputs!$B$9)/Inputs!$B$7/Inputs!$B$6) -> 74.981328 | G44: =IF(G$37<=$A44,"n.m.",(SUMPRODUCT($B$5:$G$5,(1+G$37)^(-DCF!$B$6:$G$6))-$B$5*Inputs!$B$20*(1+G$37)^(-DCF!$B$6)+IF(Inputs!$B$21=1,Forecast!$H$14*(1+$A44)*(1-$A44/Inputs!$B$22),$G$5*(1+$A44))/(G$37-$A44)/(1+G$37)^(6-Inputs!$B$19)-Inputs!$B$8-Inputs!$B$9)/Inputs!$B$7/Inputs!$B$6) -> 69.433082 | H44: =IF(H$37<=$A44,"n.m.",(SUMPRODUCT($B$5:$G$5,(1+H$37)^(-DCF!$B$6:$G$6))-$B$5*Inputs!$B$20*(1+H$37)^(-DCF!$B$6)+IF(Inputs!$B$21=1,Forecast!$H$14*(1+$A44)*(1-$A44/Inputs!$B$22),$G$5*(1+$A44))/(H$37-$A44)/(1+H$37)^(6-Inputs!$B$19)-Inputs!$B$8-Inputs!$B$9)/Inputs!$B$7/Inputs!$B$6) -> 64.671846

Sheet Scenarios
A1: Scenario analysis
A2: Shifts are additive to the base case (Inputs sheet). Edit the blue cells; every scenario re-runs the full forecast.
A4: Scenario | B4: Probability | C4: Growth shift | D4: Margin shift | E4: WACC shift | F4: Terminal g shift | G4: WACC | H4: Terminal growth | I4: Value per share (NOK) | J4: vs price
A5: Bear | B5: 0.25 | C5: -0.02 | D5: -0.015 | E5: 0.005 | F5: -0.0025 | G5: =WACC!$B$17+E5 -> 0.088 | H5: =Inputs!$B$11+F5 -> 0.0175 | I5: =B25 -> 52.933294 | J5: =I5/Inputs!$B$5-1 -> 0.11673616
A6: Base | B6: 0.5 | C6: 0 | D6: 0 | E6: 0 | F6: 0 | G6: =WACC!$B$17+E6 -> 0.083 | H6: =Inputs!$B$11+F6 -> 0.02 | I6: =B40 -> 73.995407 | J6: =I6/Inputs!$B$5-1 -> 0.56108453
A7: Bull | B7: 0.25 | C7: 0.02 | D7: 0.015 | E7: -0.005 | F7: 0.0025 | G7: =WACC!$B$17+E7 -> 0.078 | H7: =Inputs!$B$11+F7 -> 0.0225 | I7: =B55 -> 103.48645 | J7: =I7/Inputs!$B$5-1 -> 1.1832584
A8: Probability-weighted | B8: =SUM(B5:B7) -> 1 | I8: =IFERROR(SUMPRODUCT(B5:B7,I5:I7)/B8,"") -> 76.102639 | J8: =IFERROR(I8/Inputs!$B$5-1,"") -> 0.60554092
A12: Bear case (NOKm) | B12: =Forecast!B4 -> 2025A | C12: 2026E | D12: 2027E | E12: 2028E | F12: 2029E | G12: 2030E | H12: 2031E
A13: Revenue growth | C13: =Inputs!B33+$C$5 -> -0.0053 | D13: =Inputs!C33+$C$5 -> 0.0576 | E13: =Inputs!D33+$C$5 -> 0.0432 | F13: =Inputs!E33+$C$5 -> 0.0288 | G13: =Inputs!F33+$C$5 -> 0.0144 | H13: =Inputs!G33+$C$5 -> 0
A14: Revenue | B14: =Forecast!B6 -> 3912.343 | C14: =B14*(1+C13) -> 3891.6076 | D14: =C14*(1+D13) -> 4115.7642 | E14: =D14*(1+E13) -> 4293.5652 | F14: =E14*(1+F13) -> 4417.2199 | G14: =F14*(1+G13) -> 4480.8278 | H14: =G14*(1+H13) -> 4480.8278
A15: EBITDA margin | C15: =Inputs!B34+$D$5 -> 0.11956663 | D15: =Inputs!C34+$D$5 -> 0.11994102 | E15: =Inputs!D34+$D$5 -> 0.1203154 | F15: =Inputs!E34+$D$5 -> 0.12068979 | G15: =Inputs!F34+$D$5 -> 0.12106417 | H15: =Inputs!G34+$D$5 -> 0.12143856
A16: EBITDA | C16: =C14*C15 -> 465.30641 | D16: =D14*D15 -> 493.64894 | E16: =E14*E15 -> 516.58202 | F16: =F14*F15 -> 533.11333 | G16: =G14*G15 -> 542.46772 | H16: =H14*H15 -> 544.14528
A17: D&A | C17: =C14*Inputs!B35 -> 50.521415 | D17: =D14*Inputs!C35 -> 53.431449 | E17: =E14*Inputs!D35 -> 55.739687 | F17: =F14*Inputs!E35 -> 57.34499 | G17: =G14*Inputs!F35 -> 58.170758 | H17: =H14*Inputs!G35 -> 58.170758
A18: EBIT | C18: =C16-C17 -> 414.78499 | D18: =D16-D17 -> 440.21749 | E18: =E16-E17 -> 460.84234 | F18: =F16-F17 -> 475.76834 | G18: =G16-G17 -> 484.29697 | H18: =H16-H17 -> 485.97453
A19: Tax | C19: =-MAX(C18,0)*Inputs!$B$10 -> -91.252698 | D19: =-MAX(D18,0)*Inputs!$B$10 -> -96.847848 | E19: =-MAX(E18,0)*Inputs!$B$10 -> -101.38531 | F19: =-MAX(F18,0)*Inputs!$B$10 -> -104.66904 | G19: =-MAX(G18,0)*Inputs!$B$10 -> -106.54533 | H19: =-MAX(H18,0)*Inputs!$B$10 -> -106.9144
A20: NOPAT | C20: =C18+C19 -> 323.53229 | D20: =D18+D19 -> 343.36964 | E20: =E18+E19 -> 359.45702 | F20: =F18+F19 -> 371.09931 | G20: =G18+G19 -> 377.75163 | H20: =H18+H19 -> 379.06013
A21: Capex | C21: =-C14*Inputs!B36 -> -39.779148 | D21: =-D14*Inputs!C36 -> -42.070427 | E21: =-E14*Inputs!D36 -> -43.88787 | F21: =-F14*Inputs!E36 -> -45.15184 | G21: =-G14*Inputs!F36 -> -45.802027 | H21: =-H14*Inputs!G36 -> -45.802027
A22: Change in NWC | C22: =-Inputs!B37*(C14-B14) -> -1.4442 | D22: =-Inputs!C37*(D14-C14) -> 15.612271 | E22: =-Inputs!D37*(E14-D14) -> 12.383653 | F22: =-Inputs!E37*(F14-E14) -> 8.6124181 | G22: =-Inputs!F37*(G14-F14) -> 4.4302279 | H22: =-Inputs!G37*(H14-G14) -> 0
A23: Unlevered FCF | C23: =C20+C17+C21+C22 -> 332.83036 | D23: =D20+D17+D21+D22 -> 370.34293 | E23: =E20+E17+E21+E22 -> 383.69249 | F23: =F20+F17+F21+F22 -> 391.90487 | G23: =G20+G17+G21+G22 -> 394.55059 | H23: =H20+H17+H21+H22 -> 391.42886
A24: Enterprise value | B24: =SUMPRODUCT($C$23:$H$23,(1+$G$5)^(-DCF!$B$6:$G$6))-$C$23*Inputs!$B$20*(1+$G$5)^(-DCF!$B$6)+IF(Inputs!$B$21=1,$H$20*(1+$H$5)*(1-$H$5/Inputs!$B$22),$H$23*(1+$H$5))/($G$5-$H$5)/(1+$G$5)^(6-Inputs!$B$19) -> 5258.6805
A25: Value per share (NOK) | B25: =(B24-Inputs!$B$8-Inputs!$B$9)/Inputs!$B$7/Inputs!$B$6 -> 52.933294
A27: Base case (NOKm) | B27: =Forecast!B4 -> 2025A | C27: 2026E | D27: 2027E | E27: 2028E | F27: 2029E | G27: 2030E | H27: 2031E
A28: Revenue growth | C28: =Inputs!B33+$C$6 -> 0.0147 | D28: =Inputs!C33+$C$6 -> 0.0776 | E28: =Inputs!D33+$C$6 -> 0.0632 | F28: =Inputs!E33+$C$6 -> 0.0488 | G28: =Inputs!F33+$C$6 -> 0.0344 | H28: =Inputs!G33+$C$6 -> 0.02
A29: Revenue | B29: =Forecast!B6 -> 3912.343 | C29: =B29*(1+C28) -> 3969.8544 | D29: =C29*(1+D28) -> 4277.9151 | E29: =D29*(1+E28) -> 4548.2794 | F29: =E29*(1+F28) -> 4770.2354 | G29: =F29*(1+G28) -> 4934.3315 | H29: =G29*(1+H28) -> 5033.0181
A30: EBITDA margin | C30: =Inputs!B34+$D$6 -> 0.13456663 | D30: =Inputs!C34+$D$6 -> 0.13494102 | E30: =Inputs!D34+$D$6 -> 0.1353154 | F30: =Inputs!E34+$D$6 -> 0.13568979 | G30: =Inputs!F34+$D$6 -> 0.13606417 | H30: =Inputs!G34+$D$6 -> 0.13643856
A31: EBITDA | C31: =C29*C30 -> 534.20994 | D31: =D29*D30 -> 577.26622 | E31: =E29*E30 -> 615.45226 | F31: =F29*F30 -> 647.27224 | G31: =G29*G30 -> 671.38575 | H31: =H29*H30 -> 686.69775
A32: D&A | C32: =C29*Inputs!B35 -> 51.537227 | D32: =D29*Inputs!C35 -> 55.536516 | E32: =E29*Inputs!D35 -> 59.046424 | F32: =F29*Inputs!E35 -> 61.927889 | G32: =G29*Inputs!F35 -> 64.058209 | H32: =H29*Inputs!G35 -> 65.339373
A33: EBIT | C33: =C31-C32 -> 482.67271 | D33: =D31-D32 -> 521.7297 | E33: =E31-E32 -> 556.40583 | F33: =F31-F32 -> 585.34435 | G33: =G31-G32 -> 607.32754 | H33: =H31-H32 -> 621.35838
A34: Tax | C34: =-MAX(C33,0)*Inputs!$B$10 -> -106.188 | D34: =-MAX(D33,0)*Inputs!$B$10 -> -114.78053 | E34: =-MAX(E33,0)*Inputs!$B$10 -> -122.40928 | F34: =-MAX(F33,0)*Inputs!$B$10 -> -128.77576 | G34: =-MAX(G33,0)*Inputs!$B$10 -> -133.61206 | H34: =-MAX(H33,0)*Inputs!$B$10 -> -136.69884
A35: NOPAT | C35: =C33+C34 -> 376.48471 | D35: =D33+D34 -> 406.94917 | E35: =E33+E34 -> 433.99655 | F35: =F33+F34 -> 456.56859 | G35: =G33+G34 -> 473.71548 | H35: =H33+H34 -> 484.65954
A36: Capex | C36: =-C29*Inputs!B36 -> -40.57897 | D36: =-D29*Inputs!C36 -> -43.727898 | E36: =-E29*Inputs!D36 -> -46.491501 | F36: =-F29*Inputs!E36 -> -48.760287 | G36: =-G29*Inputs!F36 -> -50.437641 | H36: =-H29*Inputs!G36 -> -51.446393
A37: Change in NWC | C37: =-Inputs!B37*(C29-B29) -> 4.0056114 | D37: =-Inputs!C37*(D29-C29) -> 21.456104 | E37: =-Inputs!D37*(E29-D29) -> 18.830584 | F37: =-Inputs!E37*(F29-E29) -> 15.459004 | G37: =-Inputs!F37*(G29-F29) -> 11.42912 | H37: =-Inputs!G37*(H29-G29) -> 6.8734199
A38: Unlevered FCF | C38: =C35+C32+C36+C37 -> 391.44858 | D38: =D35+D32+D36+D37 -> 440.21389 | E38: =E35+E32+E36+E37 -> 465.38206 | F38: =F35+F32+F36+F37 -> 485.1952 | G38: =G35+G32+G36+G37 -> 498.76517 | H38: =H35+H32+H36+H37 -> 505.42594
A39: Enterprise value | B39: =SUMPRODUCT($C$38:$H$38,(1+$G$6)^(-DCF!$B$6:$G$6))-$C$38*Inputs!$B$20*(1+$G$6)^(-DCF!$B$6)+IF(Inputs!$B$21=1,$H$35*(1+$H$6)*(1-$H$6/Inputs!$B$22),$H$38*(1+$H$6))/($G$6-$H$6)/(1+$G$6)^(6-Inputs!$B$19) -> 7414.6627
A40: Value per share (NOK) | B40: =(B39-Inputs!$B$8-Inputs!$B$9)/Inputs!$B$7/Inputs!$B$6 -> 73.995407
A42: Bull case (NOKm) | B42: =Forecast!B4 -> 2025A | C42: 2026E | D42: 2027E | E42: 2028E | F42: 2029E | G42: 2030E | H42: 2031E
A43: Revenue growth | C43: =Inputs!B33+$C$7 -> 0.0347 | D43: =Inputs!C33+$C$7 -> 0.0976 | E43: =Inputs!D33+$C$7 -> 0.0832 | F43: =Inputs!E33+$C$7 -> 0.0688 | G43: =Inputs!F33+$C$7 -> 0.0544 | H43: =Inputs!G33+$C$7 -> 0.04
A44: Revenue | B44: =Forecast!B6 -> 3912.343 | C44: =B44*(1+C43) -> 4048.1013 | D44: =C44*(1+D43) -> 4443.196 | E44: =D44*(1+E43) -> 4812.8699 | F44: =E44*(1+F43) -> 5143.9953 | G44: =F44*(1+G43) -> 5423.8287 | H44: =G44*(1+H43) -> 5640.7818
A45: EBITDA margin | C45: =Inputs!B34+$D$7 -> 0.14956663 | D45: =Inputs!C34+$D$7 -> 0.14994102 | E45: =Inputs!D34+$D$7 -> 0.1503154 | F45: =Inputs!E34+$D$7 -> 0.15068979 | G45: =Inputs!F34+$D$7 -> 0.15106417 | H45: =Inputs!G34+$D$7 -> 0.15143856
A46: EBITDA | C46: =C44*C45 -> 605.46087 | D46: =D44*D45 -> 666.21732 | E46: =E44*E45 -> 723.44848 | F46: =F44*F45 -> 775.14757 | G46: =G44*G45 -> 819.3462 | H46: =H44*H45 -> 854.23188
...

Sheet Peers
A1: Peer multiples
A2: LTM figures where the quarters are reported (else the last fiscal year); EV = market cap today + latest net debt, same lease basis as the target company; P/E on trailing twelve-month EPS.
A4: Company | B4: Ticker | C4: Group | D4: Market cap (NOKm) | E4: EV (NOKm) | F4: Rev. growth | G4: EBITDA margin | H4: EV/Sales | I4: EV/EBITDA | J4: EV/EBIT | K4: P/E | L4: P/E (NTM) | M4: EV/Sales (NTM) | N4: EV/EBITDA (NTM*) | O4: P/E (FY0) | P4: P/E (FY1) | Q4: Growth FY1 | R4: EPS growth | S4: PEG | T4: FCF yield | U4: Div. yield
A5: Knowit | B5: KNOW.ST | C5: Nordic IT services | D5: 2423.1751 | E5: 2924.2345 | F5: -0.096288599 | G5: 0.086789313 | H5: 0.54439623 | I5: 6.2726183 | L5: 13.184524 | M5: 0.51878364 | N5: 5.977506 | O5: 14.79552 | P5: 12.671499 | Q5: 0.047581535 | R5: 0.16762191 | S5: 0.78656325 | T5: 0.12091861 | U5: 0.026968716
A6: Tietoevry | B6: TIETO.HE | C6: Nordic IT services | D6: 22273.999 | E6: 25742.595 | F6: -0.014471934 | G6: 0.18549723 | H6: 1.3255698 | I6: 7.1460356 | J6: 7.8935248 | K6: 9.873015 | L6: 11.371886 | M6: 1.355845 | N6: 7.3092466 | O6: 11.772871 | P6: 11.229667 | Q6: 0.006318084 | R6: 0.04837224 | S6: 2.3509115 | T6: 0.087152927 | U6: 0.0471597
A7: Netcompany | B7: NETC.CO | C7: Nordic IT services | D7: 20420.67 | E7: 25026.703 | F7: 0.20657126 | G7: 0.098755533 | H7: 1.8585548 | I7: 18.819754 | J7: 26.576876 | K7: 34.895947 | L7: 14.5503 | M7: 1.7053532 | N7: 17.268432 | O7: 18.425238 | P7: 13.495014 | Q7: 0.079394535 | R7: 0.36533673 | S7: 0.39827095 | T7: 0.012608531
A8: Atea | B8: ATEA.OL | C8: Nordic IT services | D8: 19121.383 | E8: 20385.383 | F8: 0.080918503 | G8: 0.047867959 | H8: 0.51269796 | I8: 10.710671 | J8: 12.940358 | K8: 16.673151 | L8: 15.186763 | M8: 0.48169418 | N8: 10.062977 | O8: 16.386233 | P8: 14.784363 | Q8: 0.034908327 | R8: 0.10834895 | S8: 1.4016531 | T8: 0.01819952 | U8: 0.043757293
A9: Sopra Steria | B9: SOP.PA | C9: European IT services | D9: 33798.317 | E9: 41167.594 | F9: -0.022296081 | G9: 0.088277576 | H9: 0.67307586 | I9: 7.6245394 | J9: 8.8471153 | K9: 10.392535 | L9: 8.271223 | M9: 0.63167461 | N9: 7.15555 | O9: 8.9004156 | P9: 8.0593769 | Q9: 0.038130922 | R9: 0.10435531 | S9: 0.79260205 | T9: 0.11749317 | U9: 0.032817337
A10: Capgemini | B10: CAP.PA | C10: European IT services | D10: 191092.62 | E10: 264752.91 | F10: 0.016699855 | G10: 0.1212022 | H10: 1.0882722 | I10: 8.9789803 | J10: 10.53428 | K10: 13.506989 | L10: 7.9093568 | M10: 0.97606469 | N10: 8.0531926 | O10: 8.3800688 | P10: 7.7475424 | Q10: 0.042978721 | R10: 0.08164221 | S10: 0.96878279 | T10: 0.10761624 | U10: 0.031984948
A11: Reply | B11: REY.MI | C11: European IT services | D11: 46697.301 | E11: 41599.245 | F11: 0.067098066 | G11: 0.16828795 | H11: 1.5203115 | I11: 9.0339891 | J11: 9.8478416 | K11: 17.00573 | L11: 14.561277 | M11: 1.3402311 | N11: 7.9639161 | O11: 15.420892 | P11: 14.265592 | Q11: 0.079588734 | R11: 0.080985014 | S11: 1.7980212 | T11: 0.0565714 | U11: 0.01137321
A12: Accenture | B12: ACN | C12: Global IT services | D12: 1067187.6 | E12: 1035029.7 | F12: 0.073602053 | G12: 0.1667019 | H12: 1.4995756 | I12: 8.9955523 | J12: 10.17779 | K12: 14.740623 | L12: 12.585516 | M12: 1.4318855 | N12: 8.5894976 | O12: 13.320275 | P12: 12.585516 | Q12: 0.040655462 | R12: 0.058381316 | S12: 2.1557438 | T12: 0.096211389 | U12: 0.035300487
A14: Average | F14: =IFERROR(AVERAGE(F5:F12),"") -> 0.038979141 | G14: =IFERROR(AVERAGE(G5:G12),"") -> 0.12042246 | H14: =IFERROR(AVERAGE(H5:H12),"") -> 1.1278067 | I14: =IFERROR(AVERAGE(I5:I12),"") -> 9.6977675 | J14: =IFERROR(AVERAGE(J5:J12),"") -> 12.402541 | K14: =IFERROR(AVERAGE(K5:K12),"") -> 16.726856 | L14: =IFERROR(AVERAGE(L5:L12),"") -> 12.202606 | M14: =IFERROR(AVERAGE(M5:M12),"") -> 1.0551915 | ... U14: =IFERROR(AVERAGE(U5:U12),"") -> 0.032765956
A15: Median | F15: =IFERROR(MEDIAN(F5:F12),"") -> 0.041898961 | G15: =IFERROR(MEDIAN(G5:G12),"") -> 0.10997887 | H15: =IFERROR(MEDIAN(H5:H12),"") -> 1.206921 | I15: =IFERROR(MEDIAN(I5:I12),"") -> 8.9872663 | J15: =IFERROR(MEDIAN(J5:J12),"") -> 10.17779 | K15: =IFERROR(MEDIAN(K5:K12),"") -> 14.740623 | L15: =IFERROR(MEDIAN(L5:L12),"") -> 12.88502 | M15: =IFERROR(MEDIAN(M5:M12),"") -> 1.1581479 | ... U15: =IFERROR(MEDIAN(U5:U12),"") -> 0.032817337
A16: 25th percentile | F16: =IFERROR(QUARTILE(F5:F12,1),"") -> -0.016427971 | G16: =IFERROR(QUARTILE(G5:G12,1),"") -> 0.08790551 | H16: =IFERROR(QUARTILE(H5:H12,1),"") -> 0.64090595 | I16: =IFERROR(QUARTILE(I5:I12,1),"") -> 7.5049135 | J16: =IFERROR(QUARTILE(J5:J12,1),"") -> 9.3474784 | K16: =IFERROR(QUARTILE(K5:K12,1),"") -> 11.949762 | L16: =IFERROR(QUARTILE(L5:L12,1),"") -> 10.59672 | M16: =IFERROR(QUARTILE(M5:M12,1),"") -> 0.60345187 | ... U16: =IFERROR(QUARTILE(U5:U12,1),"") -> 0.029476832
A17: 75th percentile | F17: =IFERROR(QUARTILE(F5:F12,3),"") -> 0.075431166 | G17: =IFERROR(QUARTILE(G5:G12,3),"") -> 0.16709841 | H17: =IFERROR(QUARTILE(H5:H12,3),"") -> 1.5047596 | I17: =IFERROR(QUARTILE(I5:I12,3),"") -> 9.4531595 | J17: =IFERROR(QUARTILE(J5:J12,3),"") -> 11.737319 | K17: =IFERROR(QUARTILE(K5:K12,3),"") -> 16.839441 | L17: =IFERROR(QUARTILE(L5:L12,3),"") -> 14.553045 | M17: =IFERROR(QUARTILE(M5:M12,3),"") -> 1.3748551 | ... U17: =IFERROR(QUARTILE(U5:U12,3),"") -> 0.03952889
A20: Bouvet – current multiples and implied value | D20: Multiple | E20: Bouvet | F20: Peer median | G20: Implied value/share (NOK) | H20: vs price
A21: Market cap | B21: =(Inputs!$B$5*Inputs!$B$6)*Inputs!$B$7 -> 4852.0087 | D21: EV/Sales | E21: =IF(B23<=0,"n.m.",B22/B23) -> 1.2090711 | F21: =H15 -> 1.206921 | G21: =IF(B23<=0,"",(H15*B23-Inputs!$B$8-Inputs!$B$9)/Inputs!$B$7/Inputs!$B$6) -> 47.318482 | H21: =IF(G21="","",G21/Inputs!$B$5-1) -> -0.0017197917
A22: Enterprise value | B22: =B21+Inputs!$B$8+Inputs!$B$9 -> 4692.2757 | D22: EV/EBITDA | E22: =IF(B24<=0,"n.m.",B22/B24) -> 9.514316 | F22: =I15 -> 8.9872663 | G22: =IF(B24<=0,"",(I15*B24-Inputs!$B$8-Inputs!$B$9)/Inputs!$B$7/Inputs!$B$6) -> 44.860698 | H22: =IF(G22="","",G22/Inputs!$B$5-1) -> -0.053571763
A23: Revenue (LTM Jun 2026) | B23: 3880.893 | D23: EV/EBIT | E23: =IF(B25<=0,"n.m.",B22/B25) -> 10.447709 | F23: =J15 -> 10.17779 | G23: =IF(B25<=0,"",(J15*B25-Inputs!$B$8-Inputs!$B$9)/Inputs!$B$7/Inputs!$B$6) -> 46.215725 | H23: =IF(G23="","",G23/Inputs!$B$5-1) -> -0.024984699
A24: EBITDA (LTM Jun 2026) | B24: 493.18056 | D24: P/E | E24: =IF(B26<=0,"n.m.",(Inputs!$B$5*Inputs!$B$6)/B26) -> 14.766355 | F24: =K15 -> 14.740623 | G24: =IF(B26<=0,"",K15*B26/Inputs!$B$6) -> 47.317398 | H24: =IF(G24="","",G24/Inputs!$B$5-1) -> -0.0017426535
A25: EBIT (LTM Jun 2026) | B25: 449.12004
A26: EPS, trailing 12 months (NOK) | B26: 3.21
A28: Income figures: sum of the four quarters to Jun 2026. Net debt: balance sheet 30.06.2026. EPS: Yahoo Finance trailing twelve months, the same basis as the peers' P/E. * EV/EBITDA (NTM) = EV over NTM consensus revenue at the LTM margin (no EBITDA consensus on Yahoo).
A30: EV/EBITDA regression on the peers above (engine OLS with an intercept; coefficients are inputs, the fitted value is live)
A31: Intercept | B31: 7.0920671
A32: Coefficient: expected revenue growth | B32: 92.987255
A33: Coefficient: EBITDA margin | B33: -14.032292
A34: R² | B34: 0.375882
A35: Residual standard deviation (x) | B35: 3.6755187
A36: Peers in the regression | B36: 8
A37: Bouvet expected revenue growth | B37: 0.077636015
A38: Bouvet EBITDA margin (LTM) | B38: =IF(B23>0,B24/B23,0) -> 0.12707914
A39: Fitted EV/EBITDA | B39: =B31+B32*B37+B33*B38 -> 12.528015 | C39: R² 0.38: used as a football-field bar (±1 residual standard deviation)
A40: Regression-implied value per share (NOK) | B40: =IF(B24<=0,"",(B39*B24-Inputs!$B$8-Inputs!$B$9)/Inputs!$B$7/Inputs!$B$6) -> 61.919867

Sheet Football field
A1: Valuation summary
A2: Ranges feed the football-field chart; DCF range = inner 3x3 of the sensitivity grid.
A4: Method | B4: Low | C4: High | D4: Range
A5: 52-week range | B5: 42.15 | C5: 67 | D5: =IFERROR(C5-B5,"") -> 24.85
A6: DCF (WACC ±0.5%, g ±0.25%) | B6: =MIN(DCF!D40:F42) -> 66.9071 | C6: =MAX(DCF!D40:F42) -> 82.983 | D6: =IFERROR(C6-B6,"") -> 16.075899
A7: EV/EBITDA (peer 25th–75th pct) | B7: =(Peers!I16*Peers!B24-Inputs!$B$8-Inputs!$B$9)/Inputs!$B$7/Inputs!$B$6 -> 37.71879 | C7: =(Peers!I17*Peers!B24-Inputs!$B$8-Inputs!$B$9)/Inputs!$B$7/Inputs!$B$6 -> 47.105351 | D7: =IFERROR(C7-B7,"") -> 9.3865615
A8: EV/EBIT (peer 25th–75th pct) | B8: =(Peers!J16*Peers!B25-Inputs!$B$8-Inputs!$B$9)/Inputs!$B$7/Inputs!$B$6 -> 42.572714 | C8: =(Peers!J17*Peers!B25-Inputs!$B$8-Inputs!$B$9)/Inputs!$B$7/Inputs!$B$6 -> 53.058189 | D8: =IFERROR(C8-B8,"") -> 10.485475
A9: P/E (peer 25th–75th pct) | B9: =Peers!K16*Peers!B26/Inputs!$B$6 -> 38.358737 | C9: =Peers!K17*Peers!B26/Inputs!$B$6 -> 54.054604 | D9: =IFERROR(C9-B9,"") -> 15.695867
A10: EV/EBITDA regression (growth, margin ±1σ) | B10: =((Peers!$B$39-Peers!$B$35)*Peers!$B$24-Inputs!$B$8-Inputs!$B$9)/Inputs!$B$7/Inputs!$B$6 -> 44.211384 | C10: =((Peers!$B$39+Peers!$B$35)*Peers!$B$24-Inputs!$B$8-Inputs!$B$9)/Inputs!$B$7/Inputs!$B$6 -> 79.62835 | D10: =IFERROR(C10-B10,"") -> 35.416966
A12: Current share price (NOK) | B12: =Inputs!$B$5 -> 47.4
A13: Target price (NOK) | B13: =DCF!$B$30 -> 77
A14: Rating | B14: =DCF!$B$33 -> BUY

Sheet Checks
A1: Model integrity checks
A2: Every check must read TRUE. A FALSE means an input or formula has been broken.
A4: Check | B4: Result | C4: What it protects against
A5: WACC exceeds terminal growth | B5: =WACC!$B$17>Inputs!$B$11 -> TRUE | C5: A perpetuity needs WACC > g
A6: Enterprise value = PV of FCF + PV of terminal value | B6: =ABS(DCF!B16-(DCF!B10+DCF!B15))<0.01 -> TRUE | C6: Broken bridge formulas
A7: Equity value = EV - net debt - minorities | B7: =ABS(DCF!B19-(DCF!B16-Inputs!$B$8-Inputs!$B$9))<0.01 -> TRUE | C7: Sign errors in the bridge
A8: Sensitivity centre equals the DCF fair value | B8: =ABS(DCF!E41-DCF!B21)<0.01 -> TRUE | C8: Sensitivity grid out of sync with the model
A9: Base scenario reproduces the DCF fair value | B9: =ABS(Scenarios!I6-DCF!B21)<0.01 -> TRUE | C9: Scenario blocks drifting from the forecast
A10: Forecast starts from the last reported revenue | B10: =Forecast!B6=Historicals!E5 -> TRUE | C10: Stale links
A11: Capital structure weights sum to 100% | B11: =ABS(WACC!B15+WACC!B16-1)<0.000001 -> TRUE | C11: WACC weights
A12: Scenario probabilities sum to 100% | B12: =ABS(Scenarios!B8-1)<0.000001 -> TRUE | C12: Probability-weighted value
A13: Share price, shares and FX are positive | B13: =AND(Inputs!$B$5>0,Inputs!$B$7>0,Inputs!$B$6>0) -> TRUE | C13: Missing market data
A14: Terminal value below 85% of enterprise value | B14: =DCF!B24<0.85 -> TRUE | C14: Valuation resting almost entirely on the perpetuity
A15: No error values in Forecast, DCF or Scenarios | B15: =SUMPRODUCT(--ISERROR(Forecast!B5:I20))+SUMPRODUCT(--ISERROR(DCF!B5:G33))+SUMPRODUCT(--ISERROR(Scenarios!B5:J8))=0 -> TRUE | C15: #REF!, #DIV/0! and friends
A17: Overall status | B17: =IF(AND(B5:B15),"ALL OK","CHECK") -> ALL OK
