Workbook

Sheet Cover
A1: Mowi ASA (MOWI.OL) – valuation model
A2: Generated by Equity Research Engine on 2026-09-23
A4: Share price (NOK) | B4: =Inputs!$B$5 -> 193.7
A5: DCF fair value per share (NOK) | B5: =DCF!B21 -> 293.47403
A6: Probability-weighted scenario value (NOK) | B6: =Scenarios!$I$8 -> 303.6837
A7: Target price (NOK) | B7: =DCF!B30 -> 308.5
A8: Upside to target price | B8: =DCF!B31 -> 0.59266908
A9: Expected total return | B9: =DCF!B32 -> 0.63190501
A10: Rating | B10: =DCF!B33 -> BUY
A11: Model checks | B11: =Checks!$B$17 -> ALL OK
A12: WACC | B12: =WACC!$B$17 -> 0.066134957
A13: Terminal growth | B13: =Inputs!$B$11 -> 0.02
A14: EV/EBITDA (LTM) | B14: =Peers!E18 -> 10.3788
A15: Peer median EV/EBITDA | B15: =Peers!F18 -> 11.249229
A18: Legend
A19: Blue text = hard-coded input (edit these)
A20: Black text = formula
A21: Green text = link to another sheet
A22: Yellow fill = key assumption
A24: Sheets: Inputs -> Historicals -> Forecast -> WACC -> DCF -> Peers -> Football field
A25: Lease treatment: operating. Sources: Company reports, Yahoo Finance, Equity Research Engine estimates
A26: Accounts in EUR; share price and per-share values in NOK (FX 0.0923 EUR per NOK on the Inputs sheet).

Sheet Inputs
A1: Mowi ASA – model inputs
A2: All figures in EURm unless stated. Blue = input, black = formula, green = link.
A4: Market data | B4: Value | C4: Source / note
A5: Share price (NOK) | B5: 193.7 | C5: Yahoo Finance close
A6: FX: EUR per NOK | B6: 0.092289999 | C6: Spot rate; per-share values are shown in the listing currency
A7: Shares outstanding (m) | B7: 527.2906 | C7: Yahoo Finance
A8: Net debt | B8: 2826.4 | C8: Balance sheet 30.06.2026 (ex leases)
A9: Minority interest | B9: 192.1 | C9: Balance sheet 30.06.2026
A10: Tax rate | B10: 0.22 | C10: config
A11: Terminal growth | B11: 0.02 | C11: Config
A12: Risk-free rate | B12: 0.038 | C12: Config
A13: Equity risk premium | B13: 0.05 | C13: Config
A14: Beta (adjusted) | B14: 0.77175878 | C14: 3y weekly regression vs OSEBX (n=156, R2=0.15), Blume-adjusted
A15: Size premium | B15: 0 | C15: size premium 0.00% (market cap USD 10.8bn)
A16: Cost of debt (pre-tax) | B16: 0.041821651 | C16: interest expense / average debt
... A29: SELL threshold (total return) | B29: -0.1 | C29: Config
A32: Forecast drivers | B32: 2026E | C32: 2027E | D32: 2028E | E32: 2029E | F32: 2030E | G32: 2031E
A33: Revenue growth | B33: 0.1163 | C33: 0.0761 | D33: 0.062075 | E33: 0.04805 | F33: 0.034025 | G33: 0.02
A34: EBITDA margin | B34: 0.2077762 | C34: 0.20647322 | D34: 0.20517024 | E34: 0.20386726 | F34: 0.20256428 | G34: 0.2012613
A35: D&A % of revenue | B35: 0.04087353 | C35: 0.04087353 | D35: 0.04087353 | E35: 0.04087353 | F35: 0.04087353 | G35: 0.04087353
A36: Capex % of revenue | B36: 0.06856528 | C36: 0.063435665 | D36: 0.05830605 | E36: 0.053176436 | F36: 0.048046821 | G36: 0.042917207
A37: Net working capital % of revenue | B37: 0.49520564 | C37: 0.49520564 | D37: 0.49520564 | E37: 0.49520564 | F37: 0.49520564 | G37: 0.49520564
A39: Notes: Revenue growth anchored on consensus (9 analysts), fading linearly to 2.0% terminal growth. EBITDA margin held near the 3-year average of 20.1%. Net working capital held at 49.5% of revenue (3-year average from the balance sheet). Capex normalises from 6.9% to 4.3% of revenue (D&A x 1.05) by 2031E.
A40: Lease treatment: operating (lease rate 4.50%). Growth anchor: consensus (9 analysts).

Sheet Historicals
A1: Mowi ASA – historical financials (EURm)
A2: Source: company reports via Yahoo Finance; lease adjustments per methodology.
A4: EURm | B4: 2022A | C4: 2023A | D4: 2024A | E4: 2025A
A5: Revenue | B5: 4907.3 | C5: 5478.3 | D5: 5566.4 | E5: 5688.7
A6: Growth | C6: =IF(B5=0,"",C5/B5-1) -> 0.11635726 | D6: =IF(C5=0,"",D5/C5-1) -> 0.016081631 | E6: =IF(D5=0,"",E5/D5-1) -> 0.021971112
A7: EBITDA (reported) | B7: 1440.1 | C7: 1415.6 | D7: 1223 | E7: 1416.4
A8: Lease cost (rent) | B8: 220.4305 | C8: 217.27575 | D8: 243.511 | E8: 227.01125
A9: EBITDA | B9: =B7-B8 -> 1219.6695 | C9: =C7-C8 -> 1198.3242 | D9: =D7-D8 -> 979.489 | E9: =E7-E8 -> 1189.3888
A10: EBITDA margin | B10: =IF(B5=0,"",B9/B5) -> 0.24854187 | C10: =IF(C5=0,"",C9/C5) -> 0.21874017 | D10: =IF(D5=0,"",D9/D5) -> 0.17596454 | E10: =IF(E5=0,"",E9/E5) -> 0.20907918
A11: D&A (reported) | B11: 386.6 | C11: 403.8 | D11: 447.8 | E11: 454
A12: Right-of-use depreciation | B12: 199.6 | C12: 196.2 | D12: 221.2 | E12: 203.6
A13: D&A | B13: =MAX(B11-B12,0) -> 187 | C13: =MAX(C11-C12,0) -> 207.6 | D13: =MAX(D11-D12,0) -> 226.6 | E13: =MAX(E11-E12,0) -> 250.4
A14: EBIT | B14: =B9-B13 -> 1032.6695 | C14: =C9-C13 -> 990.72425 | D14: =D9-D13 -> 752.889 | E14: =E9-E13 -> 938.98875
A15: EBIT margin | B15: =IF(B5=0,"",B14/B5) -> 0.21043537 | C15: =IF(C5=0,"",C14/C5) -> 0.1808452 | D15: =IF(D5=0,"",D14/D5) -> 0.135256 | E15: =IF(E5=0,"",E14/E5) -> 0.1650621
A16: Tax rate (effective, used) | B16: 0.21530622 | C16: 0.51096028 | D16: 0.24837739 | E16: 0.15112926
A17: NOPAT | B17: =B14*(1-B16) -> 810.32933 | C17: =C14*(1-C16) -> 484.50351 | D17: =D14*(1-D16) -> 565.88839 | E17: =E14*(1-E16) -> 797.08007
A18: Capex | B18: -335.2 | C18: -396.3 | D18: -374.2 | E18: -376.2
A19: Change in NWC | B19: -491.4 | C19: -173.5 | D19: -44.2 | E19: -37.5
A20: Unlevered FCF | B20: =B17+B13+B18+B19 -> 170.72933 | C20: =C17+C13+C18+C19 -> 122.30351 | D20: =D17+D13+D18+D19 -> 374.08839 | E20: =E17+E13+E18+E19 -> 633.78007
A21: FCF margin | B21: =IF(B5=0,"",B20/B5) -> 0.034790889 | C21: =IF(C5=0,"",C20/C5) -> 0.022325085 | D21: =IF(D5=0,"",D20/D5) -> 0.067204727 | E21: =IF(E5=0,"",E20/E5) -> 0.11141035
A22: Net income | B22: 782.4 | C22: 444.4 | D22: 468.5 | E22: 717.9
A23: Diluted EPS | B23: 1.51 | C23: 0.86 | D23: 0.91 | E23: 1.38
A24: Cash | B24: 170.9 | C24: 288.4 | D24: 276.7 | E24: 278
A25: Total debt (incl. leases) | B25: 2400.3 | C25: 2566.9 | D25: 2675.1 | E25: 3462.7
A26: Lease liabilities | B26: 462.9 | C26: 473.8 | D26: 517.8 | E26: 522.7
A27: Net debt (model basis) | B27: 1766.5 | C27: 1804.7 | D27: 1880.6 | E27: 2662
A28: Net debt / EBITDA | B28: =IF(B9<=0,"n.m.",B27/B9) -> 1.4483432 | C28: =IF(C9<=0,"n.m.",C27/C9) -> 1.5060198 | D28: =IF(D9<=0,"n.m.",D27/D9) -> 1.9199807 | E28: =IF(E9<=0,"n.m.",E27/E9) -> 2.2381244
A29: Interest expense (ex leases) | B29: 31.7695 | C29: 92.02425 | D29: 121.189 | E29: 106.58875

Sheet Forecast
A1: Mowi ASA – forecast (EURm)
A2: Formulas reference the Inputs sheet; last actual year is linked from Historicals.
A4: EURm | B4: 2025A | C4: 2026E | D4: 2027E | E4: 2028E | F4: 2029E | G4: 2030E | H4: 2031E | I4: Terminal
A5: Revenue growth | C5: =Inputs!B33 -> 0.1163 | D5: =Inputs!C33 -> 0.0761 | E5: =Inputs!D33 -> 0.062075 | F5: =Inputs!E33 -> 0.04805 | G5: =Inputs!F33 -> 0.034025 | H5: =Inputs!G33 -> 0.02 | I5: =Inputs!$B$11 -> 0.02
A6: Revenue | B6: =Historicals!E5 -> 5688.7 | C6: =B6*(1+C5) -> 6350.2958 | D6: =C6*(1+D5) -> 6833.5533 | E6: =D6*(1+E5) -> 7257.7461 | F6: =E6*(1+F5) -> 7606.4808 | G6: =F6*(1+G5) -> 7865.2914 | H6: =G6*(1+H5) -> 8022.5972 | I6: =H6*(1+I5) -> 8183.0491
A7: EBITDA margin | B7: =B8/B6 -> 0.20907918 | C7: =Inputs!B34 -> 0.2077762 | D7: =Inputs!C34 -> 0.20647322 | E7: =Inputs!D34 -> 0.20517024 | F7: =Inputs!E34 -> 0.20386726 | G7: =Inputs!F34 -> 0.20256428 | H7: =Inputs!G34 -> 0.2012613 | I7: =H7 -> 0.2012613
A8: EBITDA | B8: =Historicals!E9 -> 1189.3888 | C8: =C6*C7 -> 1319.4403 | D8: =D6*D7 -> 1410.9458 | E8: =E6*E7 -> 1489.0735 | F8: =F6*F7 -> 1550.7124 | G8: =G6*G7 -> 1593.2271 | H8: =H6*H7 -> 1614.6383 | I8: =I6*I7 -> 1646.9311
A9: D&A % of revenue | C9: =Inputs!B35 -> 0.04087353 | D9: =Inputs!C35 -> 0.04087353 | E9: =Inputs!D35 -> 0.04087353 | F9: =Inputs!E35 -> 0.04087353 | G9: =Inputs!F35 -> 0.04087353 | H9: =Inputs!G35 -> 0.04087353 | I9: =H9 -> 0.04087353
A10: D&A | B10: =Historicals!E13 -> 250.4 | C10: =C6*C9 -> 259.55901 | D10: =D6*D9 -> 279.31145 | E10: =E6*E9 -> 296.64971 | F10: =F6*F9 -> 310.90373 | G10: =G6*G9 -> 321.48222 | H10: =H6*H9 -> 327.91187 | I10: =I6*I9 -> 334.47011
A11: EBIT | B11: =Historicals!E14 -> 938.98875 | C11: =C8-C10 -> 1059.8813 | D11: =D8-D10 -> 1131.6343 | E11: =E8-E10 -> 1192.4238 | F11: =F8-F10 -> 1239.8087 | G11: =G8-G10 -> 1271.7448 | H11: =H8-H10 -> 1286.7264 | I11: =I8-I10 -> 1312.461
A12: EBIT margin | C12: =C11/C6 -> 0.16690267 | D12: =D11/D6 -> 0.16559969 | E12: =E11/E6 -> 0.16429671 | F12: =F11/F6 -> 0.16299373 | G12: =G11/G6 -> 0.16169075 | H12: =H11/H6 -> 0.16038777 | I12: =I11/I6 -> 0.16038777
A13: Tax | C13: =-MAX(C11,0)*Inputs!$B$10 -> -233.17389 | D13: =-MAX(D11,0)*Inputs!$B$10 -> -248.95955 | E13: =-MAX(E11,0)*Inputs!$B$10 -> -262.33324 | F13: =-MAX(F11,0)*Inputs!$B$10 -> -272.75791 | G13: =-MAX(G11,0)*Inputs!$B$10 -> -279.78386 | H13: =-MAX(H11,0)*Inputs!$B$10 -> -283.07982 | I13: =-MAX(I11,0)*Inputs!$B$10 -> -288.74141
A14: NOPAT | B14: =Historicals!E17 -> 797.08007 | C14: =C11+C13 -> 826.70744 | D14: =D11+D13 -> 882.67477 | E14: =E11+E13 -> 930.09057 | F14: =F11+F13 -> 967.05076 | G14: =G11+G13 -> 991.96097 | H14: =H11+H13 -> 1003.6466 | I14: =I11+I13 -> 1023.7195
A15: Capex % of revenue | C15: =Inputs!B36 -> 0.06856528 | D15: =Inputs!C36 -> 0.063435665 | E15: =Inputs!D36 -> 0.05830605 | F15: =Inputs!E36 -> 0.053176436 | G15: =Inputs!F36 -> 0.048046821 | H15: =Inputs!G36 -> 0.042917207 | I15: =H15 -> 0.042917207
A16: Capex | B16: =Historicals!E18 -> -376.2 | C16: =-C6*C15 -> -435.40981 | D16: =-D6*D15 -> -433.491 | E16: =-E6*E15 -> -423.17051 | F16: =-F6*F15 -> -404.48554 | G16: =-G6*G15 -> -377.90225 | H16: =-H6*H15 -> -344.30746 | I16: =-I6*I15 -> -351.19361
A17: Net working capital % of revenue | C17: =Inputs!B37 -> 0.49520564 | D17: =Inputs!C37 -> 0.49520564 | E17: =Inputs!D37 -> 0.49520564 | F17: =Inputs!E37 -> 0.49520564 | G17: =Inputs!F37 -> 0.49520564 | H17: =Inputs!G37 -> 0.49520564 | I17: =H17 -> 0.49520564
A18: Change in NWC | B18: =Historicals!E19 -> -37.5 | C18: =-C17*(C6-B6) -> -327.62597 | D18: =-D17*(D6-C6) -> -239.31184 | E18: =-E17*(E6-D6) -> -210.06268 | F18: =-F17*(F6-E6) -> -172.69539 | G18: =-G17*(G6-F6) -> -128.16442 | H18: =-H17*(H6-G6) -> -77.898732 | I18: =-I17*(I6-H6) -> -79.456707
A19: Unlevered FCF | B19: =Historicals!E20 -> 633.78007 | C19: =C14+C10+C16+C18 -> 323.23067 | D19: =D14+D10+D16+D18 -> 489.18337 | E19: =E14+E10+E16+E18 -> 593.50709 | F19: =F14+F10+F16+F18 -> 700.77356 | G19: =G14+G10+G16+G18 -> 807.37652 | H19: =H14+H10+H16+H18 -> 909.35229 | I19: =I14+I10+I16+I18 -> 927.53934
A20: FCF margin | C20: =C19/C6 -> 0.050900097 | D20: =D19/D6 -> 0.071585506 | E20: =E19/E6 -> 0.081775675 | F20: =F19/F6 -> 0.092128485 | G20: =G19/G6 -> 0.10265055 | H20: =H19/H6 -> 0.11334887 | I20: =I19/I6 -> 0.11334887

Sheet WACC
A1: Cost of capital
A2: CAPM cost of equity, after-tax cost of debt, market-value weights.
A4: Component | B4: Value
A5: Risk-free rate | B5: =Inputs!$B$12 -> 0.038
A6: Beta (adjusted) | B6: =Inputs!$B$14 -> 0.77175878 | C6: 3y weekly regression vs OSEBX (n=156, R2=0.15), Blume-adjusted
A7: Equity risk premium | B7: =Inputs!$B$13 -> 0.05
A8: Size premium | B8: =Inputs!$B$15 -> 0
A9: Cost of equity | B9: =B5+B6*B7+B8 -> 0.076587939
A10: Cost of debt (pre-tax) | B10: =Inputs!$B$16 -> 0.041821651
A11: Tax rate | B11: =Inputs!$B$10 -> 0.22
A12: Cost of debt (after tax) | B12: =B10*(1-B11) -> 0.032620888
A13: Equity value (market cap) | B13: =(Inputs!$B$5*Inputs!$B$6)*Inputs!$B$7 -> 9426.1487
A14: Debt value | B14: =Inputs!$B$17 -> 2940
A15: Weight of equity | B15: =B13/(B13+B14) -> 0.76225419
A16: Weight of debt | B16: =B14/(B13+B14) -> 0.23774581
A17: WACC | B17: =B15*B9+B16*B12 -> 0.066134957
A19: Cross-check: bottom-up beta from the peer group (Hamada, tax at the corporate rate)
A20: Median unlevered peer beta | B20: 0.46721027
A21: Relevered at the target's D/E of 0.31 | B21: 0.5808735
A22: Blume-adjusted (compare with B6) | B22: 0.71918525
A23: Peers with a usable beta | B23: 3

Sheet DCF
A1: Mowi ASA – DCF valuation (EURm)
A2: Unlevered FCF discounted at WACC; Gordon growth terminal value.
A4: Year | B4: 2026E | C4: 2027E | D4: 2028E | E4: 2029E | F4: 2030E | G4: 2031E
A5: Unlevered FCF | B5: =Forecast!C19 -> 323.23067 | C5: =Forecast!D19 -> 489.18337 | D5: =Forecast!E19 -> 593.50709 | E5: =Forecast!F19 -> 700.77356 | F5: =Forecast!G19 -> 807.37652 | G5: =Forecast!H19 -> 909.35229
A6: Discount period (years from valuation date) | B6: =IF(Inputs!$B$18=1,(1+Inputs!$B$20)/2,1)-Inputs!$B$19 -> 0.27173169 | C6: =2-Inputs!$B$19-0.5*Inputs!$B$18 -> 1.2717317 | D6: =3-Inputs!$B$19-0.5*Inputs!$B$18 -> 2.2717317 | E6: =4-Inputs!$B$19-0.5*Inputs!$B$18 -> 3.2717317 | F6: =5-Inputs!$B$19-0.5*Inputs!$B$18 -> 4.2717317 | G6: =6-Inputs!$B$19-0.5*Inputs!$B$18 -> 5.2717317
A7: Discount factor | B7: =1/(1+WACC!$B$17)^B6 -> 0.98274886 | C7: =1/(1+WACC!$B$17)^C6 -> 0.92178655 | D7: =1/(1+WACC!$B$17)^D6 -> 0.86460587 | E7: =1/(1+WACC!$B$17)^E6 -> 0.81097226 | F7: =1/(1+WACC!$B$17)^F6 -> 0.76066567 | G7: =1/(1+WACC!$B$17)^G6 -> 0.71347972
A8: PV of FCF (year 1: after the balance-sheet date) | B8: =B5*(1-Inputs!$B$20)*B7 -> 160.24053 | C8: =C5*C7 -> 450.92265 | D8: =D5*D7 -> 513.14971 | E8: =E5*E7 -> 568.30791 | F8: =F5*F7 -> 614.1436 | G8: =G5*G7 -> 648.80442
A10: Sum of PV of FCF | B10: =SUM(B8:G8) -> 2955.5688
A11: Terminal growth | B11: =Inputs!$B$11 -> 0.02
A12: WACC | B12: =WACC!$B$17 -> 0.066134957
A13: Terminal cash flow (year N+1) | B13: =IF(Inputs!$B$21=1,Forecast!$H$14*(1+B11)*(1-B11/Inputs!$B$22),$G$5*(1+B11)) -> 927.53934
A14: Terminal value | B14: =B13/(B12-B11) -> 20104.914
A15: PV of terminal value | B15: =B14/(1+B12)^(6-Inputs!$B$19) -> 14344.448
A16: Enterprise value | B16: =B10+B15 -> 17300.017
A17: Less: net debt | B17: =-Inputs!$B$8 -> -2826.4
A18: Less: minority interest | B18: =-Inputs!$B$9 -> -192.1
A19: Equity value | B19: =B16+B17+B18 -> 14281.517
A20: Shares outstanding (m) | B20: =Inputs!$B$7 -> 527.2906
A21: Fair value per share, DCF (NOK) | B21: =B19/B20/Inputs!$B$6 -> 293.47403
A22: Current share price (NOK) | B22: =Inputs!$B$5 -> 193.7
A23: Upside / (downside) to fair value | B23: =B21/B22-1 -> 0.51509567
A24: Terminal value as % of EV | B24: =B15/B16 -> 0.82915804
A25: Implied exit EV/EBITDA | B25: =B14/Forecast!H8 -> 12.451652
A26: Fair value used for the target price | B26: =Inputs!$B$26*B21+(1-Inputs!$B$26)*Inputs!$B$27 -> 293.47403
A27: Cost of equity | B27: =WACC!$B$9 -> 0.076587939
A28: Expected dividend per share (NOK) | B28: =IF(Inputs!$B$24>0,Inputs!$B$23,0) -> 7.6
A29: Target price before rounding | B29: =IF(B26<=0,0,B26*(1+B27)^(Inputs!$B$24/12)-B28) -> 308.3506
A30: Target price (NOK) | B30: =IF(Inputs!$B$25>0,MROUND(B29,Inputs!$B$25),B29) -> 308.5
A31: Upside to target price | B31: =B30/B22-1 -> 0.59266908
A32: Expected total return (incl. dividend) | B32: =(B30+B28)/B22-1 -> 0.63190501
A33: Rating | B33: =IF(B26<=0,"NOT RATED",IF(B32>=Inputs!$B$28,"BUY",IF(B32<=Inputs!$B$29,"SELL","HOLD"))) -> BUY
A36: Sensitivity: value per share (rows = terminal growth, columns = WACC)
A37: g \ WACC | B37: =WACC!$B$17+(-3)*0.005 -> 0.051134957 | C37: =WACC!$B$17+(-2)*0.005 -> 0.056134957 | D37: =WACC!$B$17+(-1)*0.005 -> 0.061134957 | E37: =WACC!$B$17+(0)*0.005 -> 0.066134957 | F37: =WACC!$B$17+(1)*0.005 -> 0.071134957 | G37: =WACC!$B$17+(2)*0.005 -> 0.076134957 | H37: =WACC!$B$17+(3)*0.005 -> 0.081134957
A38: =Inputs!$B$11+(-3)*0.0025 -> 0.0125 | B38: =IF(B$37<=$A38,"n.m.",(SUMPRODUCT($B$5:$G$5,(1+B$37)^(-DCF!$B$6:$G$6))-$B$5*Inputs!$B$20*(1+B$37)^(-DCF!$B$6)+IF(Inputs!$B$21=1,Forecast!$H$14*(1+$A38)*(1-$A38/Inputs!$B$22),$G$5*(1+$A38))/(B$37-$A38)/(1+B$37)^(6-Inputs!$B$19)-Inputs!$B$8-Inputs!$B$9)/Inputs!$B$7/Inputs!$B$6) -> 378.10809 | C38: =IF(C$37<=$A38,"n.m.",(SUMPRODUCT($B$5:$G$5,(1+C$37)^(-DCF!$B$6:$G$6))-$B$5*Inputs!$B$20*(1+C$37)^(-DCF!$B$6)+IF(Inputs!$B$21=1,Forecast!$H$14*(1+$A38)*(1-$A38/Inputs!$B$22),$G$5*(1+$A38))/(C$37-$A38)/(1+C$37)^(6-Inputs!$B$19)-Inputs!$B$8-Inputs!$B$9)/Inputs!$B$7/Inputs!$B$6) -> 325.73975 | D38: =IF(D$37<=$A38,"n.m.",(SUMPRODUCT($B$5:$G$5,(1+D$37)^(-DCF!$B$6:$G$6))-$B$5*Inputs!$B$20*(1+D$37)^(-DCF!$B$6)+IF(Inputs!$B$21=1,Forecast!$H$14*(1+$A38)*(1-$A38/Inputs!$B$22),$G$5*(1+$A38))/(D$37-$A38)/(1+D$37)^(6-Inputs!$B$19)-Inputs!$B$8-Inputs!$B$9)/Inputs!$B$7/Inputs!$B$6) -> 284.17484 | E38: =IF(E$37<=$A38,"n.m.",(SUMPRODUCT($B$5:$G$5,(1+E$37)^(-DCF!$B$6:$G$6))-$B$5*Inputs!$B$20*(1+E$37)^(-DCF!$B$6)+IF(Inputs!$B$21=1,Forecast!$H$14*(1+$A38)*(1-$A38/Inputs!$B$22),$G$5*(1+$A38))/(E$37-$A38)/(1+E$37)^(6-Inputs!$B$19)-Inputs!$B$8-Inputs!$B$9)/Inputs!$B$7/Inputs!$B$6) -> 250.39117 | F38: =IF(F$37<=$A38,"n.m.",(SUMPRODUCT($B$5:$G$5,(1+F$37)^(-DCF!$B$6:$G$6))-$B$5*Inputs!$B$20*(1+F$37)^(-DCF!$B$6)+IF(Inputs!$B$21=1,Forecast!$H$14*(1+$A38)*(1-$A38/Inputs!$B$22),$G$5*(1+$A38))/(F$37-$A38)/(1+F$37)^(6-Inputs!$B$19)-Inputs!$B$8-Inputs!$B$9)/Inputs!$B$7/Inputs!$B$6) -> 222.39743 | G38: =IF(G$37<=$A38,"n.m.",(SUMPRODUCT($B$5:$G$5,(1+G$37)^(-DCF!$B$6:$G$6))-$B$5*Inputs!$B$20*(1+G$37)^(-DCF!$B$6)+IF(Inputs!$B$21=1,Forecast!$H$14*(1+$A38)*(1-$A38/Inputs!$B$22),$G$5*(1+$A38))/(G$37-$A38)/(1+G$37)^(6-Inputs!$B$19)-Inputs!$B$8-Inputs!$B$9)/Inputs!$B$7/Inputs!$B$6) -> 198.82817 | H38: =IF(H$37<=$A38,"n.m.",(SUMPRODUCT($B$5:$G$5,(1+H$37)^(-DCF!$B$6:$G$6))-$B$5*Inputs!$B$20*(1+H$37)^(-DCF!$B$6)+IF(Inputs!$B$21=1,Forecast!$H$14*(1+$A38)*(1-$A38/Inputs!$B$22),$G$5*(1+$A38))/(H$37-$A38)/(1+H$37)^(6-Inputs!$B$19)-Inputs!$B$8-Inputs!$B$9)/Inputs!$B$7/Inputs!$B$6) -> 178.71586
A39: =Inputs!$B$11+(-2)*0.0025 -> 0.015 | B39: =IF(B$37<=$A39,"n.m.",(SUMPRODUCT($B$5:$G$5,(1+B$37)^(-DCF!$B$6:$G$6))-$B$5*Inputs!$B$20*(1+B$37)^(-DCF!$B$6)+IF(Inputs!$B$21=1,Forecast!$H$14*(1+$A39)*(1-$A39/Inputs!$B$22),$G$5*(1+$A39))/(B$37-$A39)/(1+B$37)^(6-Inputs!$B$19)-Inputs!$B$8-Inputs!$B$9)/Inputs!$B$7/Inputs!$B$6) -> 405.15019 | C39: =IF(C$37<=$A39,"n.m.",(SUMPRODUCT($B$5:$G$5,(1+C$37)^(-DCF!$B$6:$G$6))-$B$5*Inputs!$B$20*(1+C$37)^(-DCF!$B$6)+IF(Inputs!$B$21=1,Forecast!$H$14*(1+$A39)*(1-$A39/Inputs!$B$22),$G$5*(1+$A39))/(C$37-$A39)/(1+C$37)^(6-Inputs!$B$19)-Inputs!$B$8-Inputs!$B$9)/Inputs!$B$7/Inputs!$B$6) -> 346.35075 | D39: =IF(D$37<=$A39,"n.m.",(SUMPRODUCT($B$5:$G$5,(1+D$37)^(-DCF!$B$6:$G$6))-$B$5*Inputs!$B$20*(1+D$37)^(-DCF!$B$6)+IF(Inputs!$B$21=1,Forecast!$H$14*(1+$A39)*(1-$A39/Inputs!$B$22),$G$5*(1+$A39))/(D$37-$A39)/(1+D$37)^(6-Inputs!$B$19)-Inputs!$B$8-Inputs!$B$9)/Inputs!$B$7/Inputs!$B$6) -> 300.33344 | E39: =IF(E$37<=$A39,"n.m.",(SUMPRODUCT($B$5:$G$5,(1+E$37)^(-DCF!$B$6:$G$6))-$B$5*Inputs!$B$20*(1+E$37)^(-DCF!$B$6)+IF(Inputs!$B$21=1,Forecast!$H$14*(1+$A39)*(1-$A39/Inputs!$B$22),$G$5*(1+$A39))/(E$37-$A39)/(1+E$37)^(6-Inputs!$B$19)-Inputs!$B$8-Inputs!$B$9)/Inputs!$B$7/Inputs!$B$6) -> 263.3479 | F39: =IF(F$37<=$A39,"n.m.",(SUMPRODUCT($B$5:$G$5,(1+F$37)^(-DCF!$B$6:$G$6))-$B$5*Inputs!$B$20*(1+F$37)^(-DCF!$B$6)+IF(Inputs!$B$21=1,Forecast!$H$14*(1+$A39)*(1-$A39/Inputs!$B$22),$G$5*(1+$A39))/(F$37-$A39)/(1+F$37)^(6-Inputs!$B$19)-Inputs!$B$8-Inputs!$B$9)/Inputs!$B$7/Inputs!$B$6) -> 232.98 | G39: =IF(G$37<=$A39,"n.m.",(SUMPRODUCT($B$5:$G$5,(1+G$37)^(-DCF!$B$6:$G$6))-$B$5*Inputs!$B$20*(1+G$37)^(-DCF!$B$6)+IF(Inputs!$B$21=1,Forecast!$H$14*(1+$A39)*(1-$A39/Inputs!$B$22),$G$5*(1+$A39))/(G$37-$A39)/(1+G$37)^(6-Inputs!$B$19)-Inputs!$B$8-Inputs!$B$9)/Inputs!$B$7/Inputs!$B$6) -> 207.60537 | H39: =IF(H$37<=$A39,"n.m.",(SUMPRODUCT($B$5:$G$5,(1+H$37)^(-DCF!$B$6:$G$6))-$B$5*Inputs!$B$20*(1+H$37)^(-DCF!$B$6)+IF(Inputs!$B$21=1,Forecast!$H$14*(1+$A39)*(1-$A39/Inputs!$B$22),$G$5*(1+$A39))/(H$37-$A39)/(1+H$37)^(6-Inputs!$B$19)-Inputs!$B$8-Inputs!$B$9)/Inputs!$B$7/Inputs!$B$6) -> 186.09092
A40: =Inputs!$B$11+(-1)*0.0025 -> 0.0175 | B40: =IF(B$37<=$A40,"n.m.",(SUMPRODUCT($B$5:$G$5,(1+B$37)^(-DCF!$B$6:$G$6))-$B$5*Inputs!$B$20*(1+B$37)^(-DCF!$B$6)+IF(Inputs!$B$21=1,Forecast!$H$14*(1+$A40)*(1-$A40/Inputs!$B$22),$G$5*(1+$A40))/(B$37-$A40)/(1+B$37)^(6-Inputs!$B$19)-Inputs!$B$8-Inputs!$B$9)/Inputs!$B$7/Inputs!$B$6) -> 436.21222 | C40: =IF(C$37<=$A40,"n.m.",(SUMPRODUCT($B$5:$G$5,(1+C$37)^(-DCF!$B$6:$G$6))-$B$5*Inputs!$B$20*(1+C$37)^(-DCF!$B$6)+IF(Inputs!$B$21=1,Forecast!$H$14*(1+$A40)*(1-$A40/Inputs!$B$22),$G$5*(1+$A40))/(C$37-$A40)/(1+C$37)^(6-Inputs!$B$19)-Inputs!$B$8-Inputs!$B$9)/Inputs!$B$7/Inputs!$B$6) -> 369.62914 | D40: =IF(D$37<=$A40,"n.m.",(SUMPRODUCT($B$5:$G$5,(1+D$37)^(-DCF!$B$6:$G$6))-$B$5*Inputs!$B$20*(1+D$37)^(-DCF!$B$6)+IF(Inputs!$B$21=1,Forecast!$H$14*(1+$A40)*(1-$A40/Inputs!$B$22),$G$5*(1+$A40))/(D$37-$A40)/(1+D$37)^(6-Inputs!$B$19)-Inputs!$B$8-Inputs!$B$9)/Inputs!$B$7/Inputs!$B$6) -> 318.3436 | E40: =IF(E$37<=$A40,"n.m.",(SUMPRODUCT($B$5:$G$5,(1+E$37)^(-DCF!$B$6:$G$6))-$B$5*Inputs!$B$20*(1+E$37)^(-DCF!$B$6)+IF(Inputs!$B$21=1,Forecast!$H$14*(1+$A40)*(1-$A40/Inputs!$B$22),$G$5*(1+$A40))/(E$37-$A40)/(1+E$37)^(6-Inputs!$B$19)-Inputs!$B$8-Inputs!$B$9)/Inputs!$B$7/Inputs!$B$6) -> 277.63668 | F40: =IF(F$37<=$A40,"n.m.",(SUMPRODUCT($B$5:$G$5,(1+F$37)^(-DCF!$B$6:$G$6))-$B$5*Inputs!$B$20*(1+F$37)^(-DCF!$B$6)+IF(Inputs!$B$21=1,Forecast!$H$14*(1+$A40)*(1-$A40/Inputs!$B$22),$G$5*(1+$A40))/(F$37-$A40)/(1+F$37)^(6-Inputs!$B$19)-Inputs!$B$8-Inputs!$B$9)/Inputs!$B$7/Inputs!$B$6) -> 244.5491 | G40: =IF(G$37<=$A40,"n.m.",(SUMPRODUCT($B$5:$G$5,(1+G$37)^(-DCF!$B$6:$G$6))-$B$5*Inputs!$B$20*(1+G$37)^(-DCF!$B$6)+IF(Inputs!$B$21=1,Forecast!$H$14*(1+$A40)*(1-$A40/Inputs!$B$22),$G$5*(1+$A40))/(G$37-$A40)/(1+G$37)^(6-Inputs!$B$19)-Inputs!$B$8-Inputs!$B$9)/Inputs!$B$7/Inputs!$B$6) -> 217.13103 | H40: =IF(H$37<=$A40,"n.m.",(SUMPRODUCT($B$5:$G$5,(1+H$37)^(-DCF!$B$6:$G$6))-$B$5*Inputs!$B$20*(1+H$37)^(-DCF!$B$6)+IF(Inputs!$B$21=1,Forecast!$H$14*(1+$A40)*(1-$A40/Inputs!$B$22),$G$5*(1+$A40))/(H$37-$A40)/(1+H$37)^(6-Inputs!$B$19)-Inputs!$B$8-Inputs!$B$9)/Inputs!$B$7/Inputs!$B$6) -> 194.04545
A41: =Inputs!$B$11+(0)*0.0025 -> 0.02 | B41: =IF(B$37<=$A41,"n.m.",(SUMPRODUCT($B$5:$G$5,(1+B$37)^(-DCF!$B$6:$G$6))-$B$5*Inputs!$B$20*(1+B$37)^(-DCF!$B$6)+IF(Inputs!$B$21=1,Forecast!$H$14*(1+$A41)*(1-$A41/Inputs!$B$22),$G$5*(1+$A41))/(B$37-$A41)/(1+B$37)^(6-Inputs!$B$19)-Inputs!$B$8-Inputs!$B$9)/Inputs!$B$7/Inputs!$B$6) -> 472.26254 | C41: =IF(C$37<=$A41,"n.m.",(SUMPRODUCT($B$5:$G$5,(1+C$37)^(-DCF!$B$6:$G$6))-$B$5*Inputs!$B$20*(1+C$37)^(-DCF!$B$6)+IF(Inputs!$B$21=1,Forecast!$H$14*(1+$A41)*(1-$A41/Inputs!$B$22),$G$5*(1+$A41))/(C$37-$A41)/(1+C$37)^(6-Inputs!$B$19)-Inputs!$B$8-Inputs!$B$9)/Inputs!$B$7/Inputs!$B$6) -> 396.12857 | D41: =IF(D$37<=$A41,"n.m.",(SUMPRODUCT($B$5:$G$5,(1+D$37)^(-DCF!$B$6:$G$6))-$B$5*Inputs!$B$20*(1+D$37)^(-DCF!$B$6)+IF(Inputs!$B$21=1,Forecast!$H$14*(1+$A41)*(1-$A41/Inputs!$B$22),$G$5*(1+$A41))/(D$37-$A41)/(1+D$37)^(6-Inputs!$B$19)-Inputs!$B$8-Inputs!$B$9)/Inputs!$B$7/Inputs!$B$6) -> 338.54292 | E41: =IF(E$37<=$A41,"n.m.",(SUMPRODUCT($B$5:$G$5,(1+E$37)^(-DCF!$B$6:$G$6))-$B$5*Inputs!$B$20*(1+E$37)^(-DCF!$B$6)+IF(Inputs!$B$21=1,Forecast!$H$14*(1+$A41)*(1-$A41/Inputs!$B$22),$G$5*(1+$A41))/(E$37-$A41)/(1+E$37)^(6-Inputs!$B$19)-Inputs!$B$8-Inputs!$B$9)/Inputs!$B$7/Inputs!$B$6) -> 293.47403 | F41: =IF(F$37<=$A41,"n.m.",(SUMPRODUCT($B$5:$G$5,(1+F$37)^(-DCF!$B$6:$G$6))-$B$5*Inputs!$B$20*(1+F$37)^(-DCF!$B$6)+IF(Inputs!$B$21=1,Forecast!$H$14*(1+$A41)*(1-$A41/Inputs!$B$22),$G$5*(1+$A41))/(F$37-$A41)/(1+F$37)^(6-Inputs!$B$19)-Inputs!$B$8-Inputs!$B$9)/Inputs!$B$7/Inputs!$B$6) -> 257.24944 | G41: =IF(G$37<=$A41,"n.m.",(SUMPRODUCT($B$5:$G$5,(1+G$37)^(-DCF!$B$6:$G$6))-$B$5*Inputs!$B$20*(1+G$37)^(-DCF!$B$6)+IF(Inputs!$B$21=1,Forecast!$H$14*(1+$A41)*(1-$A41/Inputs!$B$22),$G$5*(1+$A41))/(G$37-$A41)/(1+G$37)^(6-Inputs!$B$19)-Inputs!$B$8-Inputs!$B$9)/Inputs!$B$7/Inputs!$B$6) -> 227.50515 | H41: =IF(H$37<=$A41,"n.m.",(SUMPRODUCT($B$5:$G$5,(1+H$37)^(-DCF!$B$6:$G$6))-$B$5*Inputs!$B$20*(1+H$37)^(-DCF!$B$6)+IF(Inputs!$B$21=1,Forecast!$H$14*(1+$A41)*(1-$A41/Inputs!$B$22),$G$5*(1+$A41))/(H$37-$A41)/(1+H$37)^(6-Inputs!$B$19)-Inputs!$B$8-Inputs!$B$9)/Inputs!$B$7/Inputs!$B$6) -> 202.65056
A42: =Inputs!$B$11+(1)*0.0025 -> 0.0225 | B42: =IF(B$37<=$A42,"n.m.",(SUMPRODUCT($B$5:$G$5,(1+B$37)^(-DCF!$B$6:$G$6))-$B$5*Inputs!$B$20*(1+B$37)^(-DCF!$B$6)+IF(Inputs!$B$21=1,Forecast!$H$14*(1+$A42)*(1-$A42/Inputs!$B$22),$G$5*(1+$A42))/(B$37-$A42)/(1+B$37)^(6-Inputs!$B$19)-Inputs!$B$8-Inputs!$B$9)/Inputs!$B$7/Inputs!$B$6) -> 514.60767 | C42: =IF(C$37<=$A42,"n.m.",(SUMPRODUCT($B$5:$G$5,(1+C$37)^(-DCF!$B$6:$G$6))-$B$5*Inputs!$B$20*(1+C$37)^(-DCF!$B$6)+IF(Inputs!$B$21=1,Forecast!$H$14*(1+$A42)*(1-$A42/Inputs!$B$22),$G$5*(1+$A42))/(C$37-$A42)/(1+C$37)^(6-Inputs!$B$19)-Inputs!$B$8-Inputs!$B$9)/Inputs!$B$7/Inputs!$B$6) -> 426.56727 | D42: =IF(D$37<=$A42,"n.m.",(SUMPRODUCT($B$5:$G$5,(1+D$37)^(-DCF!$B$6:$G$6))-$B$5*Inputs!$B$20*(1+D$37)^(-DCF!$B$6)+IF(Inputs!$B$21=1,Forecast!$H$14*(1+$A42)*(1-$A42/Inputs!$B$22),$G$5*(1+$A42))/(D$37-$A42)/(1+D$37)^(6-Inputs!$B$19)-Inputs!$B$8-Inputs!$B$9)/Inputs!$B$7/Inputs!$B$6) -> 361.35637 | E42: =IF(E$37<=$A42,"n.m.",(SUMPRODUCT($B$5:$G$5,(1+E$37)^(-DCF!$B$6:$G$6))-$B$5*Inputs!$B$20*(1+E$37)^(-DCF!$B$6)+IF(Inputs!$B$21=1,Forecast!$H$14*(1+$A42)*(1-$A42/Inputs!$B$22),$G$5*(1+$A42))/(E$37-$A42)/(1+E$37)^(6-Inputs!$B$19)-Inputs!$B$8-Inputs!$B$9)/Inputs!$B$7/Inputs!$B$6) -> 311.12614 | F42: =IF(F$37<=$A42,"n.m.",(SUMPRODUCT($B$5:$G$5,(1+F$37)^(-DCF!$B$6:$G$6))-$B$5*Inputs!$B$20*(1+F$37)^(-DCF!$B$6)+IF(Inputs!$B$21=1,Forecast!$H$14*(1+$A42)*(1-$A42/Inputs!$B$22),$G$5*(1+$A42))/(F$37-$A42)/(1+F$37)^(6-Inputs!$B$19)-Inputs!$B$8-Inputs!$B$9)/Inputs!$B$7/Inputs!$B$6) -> 271.25546 | G42: =IF(G$37<=$A42,"n.m.",(SUMPRODUCT($B$5:$G$5,(1+G$37)^(-DCF!$B$6:$G$6))-$B$5*Inputs!$B$20*(1+G$37)^(-DCF!$B$6)+IF(Inputs!$B$21=1,Forecast!$H$14*(1+$A42)*(1-$A42/Inputs!$B$22),$G$5*(1+$A42))/(G$37-$A42)/(1+G$37)^(6-Inputs!$B$19)-Inputs!$B$8-Inputs!$B$9)/Inputs!$B$7/Inputs!$B$6) -> 238.84638 | H42: =IF(H$37<=$A42,"n.m.",(SUMPRODUCT($B$5:$G$5,(1+H$37)^(-DCF!$B$6:$G$6))-$B$5*Inputs!$B$20*(1+H$37)^(-DCF!$B$6)+IF(Inputs!$B$21=1,Forecast!$H$14*(1+$A42)*(1-$A42/Inputs!$B$22),$G$5*(1+$A42))/(H$37-$A42)/(1+H$37)^(6-Inputs!$B$19)-Inputs!$B$8-Inputs!$B$9)/Inputs!$B$7/Inputs!$B$6) -> 211.98945
A43: =Inputs!$B$11+(2)*0.0025 -> 0.025 | B43: =IF(B$37<=$A43,"n.m.",(SUMPRODUCT($B$5:$G$5,(1+B$37)^(-DCF!$B$6:$G$6))-$B$5*Inputs!$B$20*(1+B$37)^(-DCF!$B$6)+IF(Inputs!$B$21=1,Forecast!$H$14*(1+$A43)*(1-$A43/Inputs!$B$22),$G$5*(1+$A43))/(B$37-$A43)/(1+B$37)^(6-Inputs!$B$19)-Inputs!$B$8-Inputs!$B$9)/Inputs!$B$7/Inputs!$B$6) -> 565.05405 | C43: =IF(C$37<=$A43,"n.m.",(SUMPRODUCT($B$5:$G$5,(1+C$37)^(-DCF!$B$6:$G$6))-$B$5*Inputs!$B$20*(1+C$37)^(-DCF!$B$6)+IF(Inputs!$B$21=1,Forecast!$H$14*(1+$A43)*(1-$A43/Inputs!$B$22),$G$5*(1+$A43))/(C$37-$A43)/(1+C$37)^(6-Inputs!$B$19)-Inputs!$B$8-Inputs!$B$9)/Inputs!$B$7/Inputs!$B$6) -> 461.89416 | D43: =IF(D$37<=$A43,"n.m.",(SUMPRODUCT($B$5:$G$5,(1+D$37)^(-DCF!$B$6:$G$6))-$B$5*Inputs!$B$20*(1+D$37)^(-DCF!$B$6)+IF(Inputs!$B$21=1,Forecast!$H$14*(1+$A43)*(1-$A43/Inputs!$B$22),$G$5*(1+$A43))/(D$37-$A43)/(1+D$37)^(6-Inputs!$B$19)-Inputs!$B$8-Inputs!$B$9)/Inputs!$B$7/Inputs!$B$6) -> 387.32651 | E43: =IF(E$37<=$A43,"n.m.",(SUMPRODUCT($B$5:$G$5,(1+E$37)^(-DCF!$B$6:$G$6))-$B$5*Inputs!$B$20*(1+E$37)^(-DCF!$B$6)+IF(Inputs!$B$21=1,Forecast!$H$14*(1+$A43)*(1-$A43/Inputs!$B$22),$G$5*(1+$A43))/(E$37-$A43)/(1+E$37)^(6-Inputs!$B$19)-Inputs!$B$8-Inputs!$B$9)/Inputs!$B$7/Inputs!$B$6) -> 330.92389 | F43: =IF(F$37<=$A43,"n.m.",(SUMPRODUCT($B$5:$G$5,(1+F$37)^(-DCF!$B$6:$G$6))-$B$5*Inputs!$B$20*(1+F$37)^(-DCF!$B$6)+IF(Inputs!$B$21=1,Forecast!$H$14*(1+$A43)*(1-$A43/Inputs!$B$22),$G$5*(1+$A43))/(F$37-$A43)/(1+F$37)^(6-Inputs!$B$19)-Inputs!$B$8-Inputs!$B$9)/Inputs!$B$7/Inputs!$B$6) -> 286.77942 | G43: =IF(G$37<=$A43,"n.m.",(SUMPRODUCT($B$5:$G$5,(1+G$37)^(-DCF!$B$6:$G$6))-$B$5*Inputs!$B$20*(1+G$37)^(-DCF!$B$6)+IF(Inputs!$B$21=1,Forecast!$H$14*(1+$A43)*(1-$A43/Inputs!$B$22),$G$5*(1+$A43))/(G$37-$A43)/(1+G$37)^(6-Inputs!$B$19)-Inputs!$B$8-Inputs!$B$9)/Inputs!$B$7/Inputs!$B$6) -> 251.29656 | H43: =IF(H$37<=$A43,"n.m.",(SUMPRODUCT($B$5:$G$5,(1+H$37)^(-DCF!$B$6:$G$6))-$B$5*Inputs!$B$20*(1+H$37)^(-DCF!$B$6)+IF(Inputs!$B$21=1,Forecast!$H$14*(1+$A43)*(1-$A43/Inputs!$B$22),$G$5*(1+$A43))/(H$37-$A43)/(1+H$37)^(6-Inputs!$B$19)-Inputs!$B$8-Inputs!$B$9)/Inputs!$B$7/Inputs!$B$6) -> 222.16017
A44: =Inputs!$B$11+(3)*0.0025 -> 0.0275 | B44: =IF(B$37<=$A44,"n.m.",(SUMPRODUCT($B$5:$G$5,(1+B$37)^(-DCF!$B$6:$G$6))-$B$5*Inputs!$B$20*(1+B$37)^(-DCF!$B$6)+IF(Inputs!$B$21=1,Forecast!$H$14*(1+$A44)*(1-$A44/Inputs!$B$22),$G$5*(1+$A44))/(B$37-$A44)/(1+B$37)^(6-Inputs!$B$19)-Inputs!$B$8-Inputs!$B$9)/Inputs!$B$7/Inputs!$B$6) -> 626.17241 | C44: =IF(C$37<=$A44,"n.m.",(SUMPRODUCT($B$5:$G$5,(1+C$37)^(-DCF!$B$6:$G$6))-$B$5*Inputs!$B$20*(1+C$37)^(-DCF!$B$6)+IF(Inputs!$B$21=1,Forecast!$H$14*(1+$A44)*(1-$A44/Inputs!$B$22),$G$5*(1+$A44))/(C$37-$A44)/(1+C$37)^(6-Inputs!$B$19)-Inputs!$B$8-Inputs!$B$9)/Inputs!$B$7/Inputs!$B$6) -> 503.38954 | D44: =IF(D$37<=$A44,"n.m.",(SUMPRODUCT($B$5:$G$5,(1+D$37)^(-DCF!$B$6:$G$6))-$B$5*Inputs!$B$20*(1+D$37)^(-DCF!$B$6)+IF(Inputs!$B$21=1,Forecast!$H$14*(1+$A44)*(1-$A44/Inputs!$B$22),$G$5*(1+$A44))/(D$37-$A44)/(1+D$37)^(6-Inputs!$B$19)-Inputs!$B$8-Inputs!$B$9)/Inputs!$B$7/Inputs!$B$6) -> 417.15724 | E44: =IF(E$37<=$A44,"n.m.",(SUMPRODUCT($B$5:$G$5,(1+E$37)^(-DCF!$B$6:$G$6))-$B$5*Inputs!$B$20*(1+E$37)^(-DCF!$B$6)+IF(Inputs!$B$21=1,Forecast!$H$14*(1+$A44)*(1-$A44/Inputs!$B$22),$G$5*(1+$A44))/(E$37-$A44)/(1+E$37)^(6-Inputs!$B$19)-Inputs!$B$8-Inputs!$B$9)/Inputs!$B$7/Inputs!$B$6) -> 353.28379 | F44: =IF(F$37<=$A44,"n.m.",(SUMPRODUCT($B$5:$G$5,(1+F$37)^(-DCF!$B$6:$G$6))-$B$5*Inputs!$B$20*(1+F$37)^(-DCF!$B$6)+IF(Inputs!$B$21=1,Forecast!$H$14*(1+$A44)*(1-$A44/Inputs!$B$22),$G$5*(1+$A44))/(F$37-$A44)/(1+F$37)^(6-Inputs!$B$19)-Inputs!$B$8-Inputs!$B$9)/Inputs!$B$7/Inputs!$B$6) -> 304.08222 | G44: =IF(G$37<=$A44,"n.m.",(SUMPRODUCT($B$5:$G$5,(1+G$37)^(-DCF!$B$6:$G$6))-$B$5*Inputs!$B$20*(1+G$37)^(-DCF!$B$6)+IF(Inputs!$B$21=1,Forecast!$H$14*(1+$A44)*(1-$A44/Inputs!$B$22),$G$5*(1+$A44))/(G$37-$A44)/(1+G$37)^(6-Inputs!$B$19)-Inputs!$B$8-Inputs!$B$9)/Inputs!$B$7/Inputs!$B$6) -> 265.02669 | H44: =IF(H$37<=$A44,"n.m.",(SUMPRODUCT($B$5:$G$5,(1+H$37)^(-DCF!$B$6:$G$6))-$B$5*Inputs!$B$20*(1+H$37)^(-DCF!$B$6)+IF(Inputs!$B$21=1,Forecast!$H$14*(1+$A44)*(1-$A44/Inputs!$B$22),$G$5*(1+$A44))/(H$37-$A44)/(1+H$37)^(6-Inputs!$B$19)-Inputs!$B$8-Inputs!$B$9)/Inputs!$B$7/Inputs!$B$6) -> 233.27903

Sheet Scenarios
A1: Scenario analysis
A2: Shifts are additive to the base case (Inputs sheet). Edit the blue cells; every scenario re-runs the full forecast.
A4: Scenario | B4: Probability | C4: Growth shift | D4: Margin shift | E4: WACC shift | F4: Terminal g shift | G4: WACC | H4: Terminal growth | I4: Value per share (NOK) | J4: vs price
A5: Bear | B5: 0.25 | C5: -0.02 | D5: -0.015 | E5: 0.005 | F5: -0.0025 | G5: =WACC!$B$17+E5 -> 0.071134957 | H5: =Inputs!$B$11+F5 -> 0.0175 | I5: =B25 -> 208.01163 | J5: =I5/Inputs!$B$5-1 -> 0.073885565
A6: Base | B6: 0.5 | C6: 0 | D6: 0 | E6: 0 | F6: 0 | G6: =WACC!$B$17+E6 -> 0.066134957 | H6: =Inputs!$B$11+F6 -> 0.02 | I6: =B40 -> 293.47403 | J6: =I6/Inputs!$B$5-1 -> 0.51509567
A7: Bull | B7: 0.25 | C7: 0.02 | D7: 0.015 | E7: -0.005 | F7: 0.0025 | G7: =WACC!$B$17+E7 -> 0.061134957 | H7: =Inputs!$B$11+F7 -> 0.0225 | I7: =B55 -> 419.77509 | J7: =I7/Inputs!$B$5-1 -> 1.1671404
A8: Probability-weighted | B8: =SUM(B5:B7) -> 1 | I8: =IFERROR(SUMPRODUCT(B5:B7,I5:I7)/B8,"") -> 303.6837 | J8: =IFERROR(I8/Inputs!$B$5-1,"") -> 0.56780432
A12: Bear case (EURm) | B12: =Forecast!B4 -> 2025A | C12: 2026E | D12: 2027E | E12: 2028E | F12: 2029E | G12: 2030E | H12: 2031E
A13: Revenue growth | C13: =Inputs!B33+$C$5 -> 0.0963 | D13: =Inputs!C33+$C$5 -> 0.0561 | E13: =Inputs!D33+$C$5 -> 0.042075 | F13: =Inputs!E33+$C$5 -> 0.02805 | G13: =Inputs!F33+$C$5 -> 0.014025 | H13: =Inputs!G33+$C$5 -> 0
A14: Revenue | B14: =Forecast!B6 -> 5688.7 | C14: =B14*(1+C13) -> 6236.5218 | D14: =C14*(1+D13) -> 6586.3907 | E14: =D14*(1+E13) -> 6863.5131 | F14: =E14*(1+F13) -> 7056.0346 | G14: =F14*(1+G13) -> 7154.9955 | H14: =G14*(1+H13) -> 7154.9955
A15: EBITDA margin | C15: =Inputs!B34+$D$5 -> 0.1927762 | D15: =Inputs!C34+$D$5 -> 0.19147322 | E15: =Inputs!D34+$D$5 -> 0.19017024 | F15: =Inputs!E34+$D$5 -> 0.18886726 | G15: =Inputs!F34+$D$5 -> 0.18756428 | H15: =Inputs!G34+$D$5 -> 0.1862613
A16: EBITDA | C16: =C14*C15 -> 1202.253 | D16: =D14*D15 -> 1261.1174 | E16: =E14*E15 -> 1305.2359 | F16: =F14*F15 -> 1332.6539 | G16: =G14*G15 -> 1342.0216 | H16: =H14*H15 -> 1332.6987
A17: D&A | C17: =C14*Inputs!B35 -> 254.90866 | D17: =D14*Inputs!C35 -> 269.20904 | E17: =E14*Inputs!D35 -> 280.53601 | F17: =F14*Inputs!E35 -> 288.40504 | G17: =G14*Inputs!F35 -> 292.44993 | H17: =H14*Inputs!G35 -> 292.44993
A18: EBIT | C18: =C16-C17 -> 947.34433 | D18: =D16-D17 -> 991.9084 | E18: =E16-E17 -> 1024.6999 | F18: =F16-F17 -> 1044.2489 | G18: =G16-G17 -> 1049.5716 | H18: =H16-H17 -> 1040.2488
A19: Tax | C19: =-MAX(C18,0)*Inputs!$B$10 -> -208.41575 | D19: =-MAX(D18,0)*Inputs!$B$10 -> -218.21985 | E19: =-MAX(E18,0)*Inputs!$B$10 -> -225.43398 | F19: =-MAX(F18,0)*Inputs!$B$10 -> -229.73475 | G19: =-MAX(G18,0)*Inputs!$B$10 -> -230.90576 | H19: =-MAX(H18,0)*Inputs!$B$10 -> -228.85474
A20: NOPAT | C20: =C18+C19 -> 738.92857 | D20: =D18+D19 -> 773.68855 | E20: =E18+E19 -> 799.26593 | F20: =F18+F19 -> 814.51412 | G20: =G18+G19 -> 818.66587 | H20: =H18+H19 -> 811.39407
A21: Capex | C21: =-C14*Inputs!B36 -> -427.60886 | D21: =-D14*Inputs!C36 -> -417.81207 | E21: =-E14*Inputs!D36 -> -400.18434 | F21: =-F14*Inputs!E36 -> -375.21477 | G21: =-G14*Inputs!F36 -> -343.77479 | H21: =-H14*Inputs!G36 -> -307.07242
A22: Change in NWC | C22: =-Inputs!B37*(C14-B14) -> -271.28445 | D22: =-Inputs!C37*(D14-C14) -> -173.25704 | E22: =-Inputs!D37*(E14-D14) -> -137.23257 | F22: =-Inputs!E37*(F14-E14) -> -95.337752 | G22: =-Inputs!F37*(G14-F14) -> -49.005988 | H22: =-Inputs!G37*(H14-G14) -> 0
A23: Unlevered FCF | C23: =C20+C17+C21+C22 -> 294.94393 | D23: =D20+D17+D21+D22 -> 451.82848 | E23: =E20+E17+E21+E22 -> 542.38503 | F23: =F20+F17+F21+F22 -> 632.36663 | G23: =G20+G17+G21+G22 -> 718.33502 | H23: =H20+H17+H21+H22 -> 796.77157
A24: Enterprise value | B24: =SUMPRODUCT($C$23:$H$23,(1+$G$5)^(-DCF!$B$6:$G$6))-$C$23*Inputs!$B$20*(1+$G$5)^(-DCF!$B$6)+IF(Inputs!$B$21=1,$H$20*(1+$H$5)*(1-$H$5/Inputs!$B$22),$H$23*(1+$H$5))/($G$5-$H$5)/(1+$G$5)^(6-Inputs!$B$19) -> 13141.105
A25: Value per share (NOK) | B25: =(B24-Inputs!$B$8-Inputs!$B$9)/Inputs!$B$7/Inputs!$B$6 -> 208.01163
A27: Base case (EURm) | B27: =Forecast!B4 -> 2025A | C27: 2026E | D27: 2027E | E27: 2028E | F27: 2029E | G27: 2030E | H27: 2031E
A28: Revenue growth | C28: =Inputs!B33+$C$6 -> 0.1163 | D28: =Inputs!C33+$C$6 -> 0.0761 | E28: =Inputs!D33+$C$6 -> 0.062075 | F28: =Inputs!E33+$C$6 -> 0.04805 | G28: =Inputs!F33+$C$6 -> 0.034025 | H28: =Inputs!G33+$C$6 -> 0.02
A29: Revenue | B29: =Forecast!B6 -> 5688.7 | C29: =B29*(1+C28) -> 6350.2958 | D29: =C29*(1+D28) -> 6833.5533 | E29: =D29*(1+E28) -> 7257.7461 | F29: =E29*(1+F28) -> 7606.4808 | G29: =F29*(1+G28) -> 7865.2914 | H29: =G29*(1+H28) -> 8022.5972
A30: EBITDA margin | C30: =Inputs!B34+$D$6 -> 0.2077762 | D30: =Inputs!C34+$D$6 -> 0.20647322 | E30: =Inputs!D34+$D$6 -> 0.20517024 | F30: =Inputs!E34+$D$6 -> 0.20386726 | G30: =Inputs!F34+$D$6 -> 0.20256428 | H30: =Inputs!G34+$D$6 -> 0.2012613
A31: EBITDA | C31: =C29*C30 -> 1319.4403 | D31: =D29*D30 -> 1410.9458 | E31: =E29*E30 -> 1489.0735 | F31: =F29*F30 -> 1550.7124 | G31: =G29*G30 -> 1593.2271 | H31: =H29*H30 -> 1614.6383
A32: D&A | C32: =C29*Inputs!B35 -> 259.55901 | D32: =D29*Inputs!C35 -> 279.31145 | E32: =E29*Inputs!D35 -> 296.64971 | F32: =F29*Inputs!E35 -> 310.90373 | G32: =G29*Inputs!F35 -> 321.48222 | H32: =H29*Inputs!G35 -> 327.91187
A33: EBIT | C33: =C31-C32 -> 1059.8813 | D33: =D31-D32 -> 1131.6343 | E33: =E31-E32 -> 1192.4238 | F33: =F31-F32 -> 1239.8087 | G33: =G31-G32 -> 1271.7448 | H33: =H31-H32 -> 1286.7264
A34: Tax | C34: =-MAX(C33,0)*Inputs!$B$10 -> -233.17389 | D34: =-MAX(D33,0)*Inputs!$B$10 -> -248.95955 | E34: =-MAX(E33,0)*Inputs!$B$10 -> -262.33324 | F34: =-MAX(F33,0)*Inputs!$B$10 -> -272.75791 | G34: =-MAX(G33,0)*Inputs!$B$10 -> -279.78386 | H34: =-MAX(H33,0)*Inputs!$B$10 -> -283.07982
A35: NOPAT | C35: =C33+C34 -> 826.70744 | D35: =D33+D34 -> 882.67477 | E35: =E33+E34 -> 930.09057 | F35: =F33+F34 -> 967.05076 | G35: =G33+G34 -> 991.96097 | H35: =H33+H34 -> 1003.6466
A36: Capex | C36: =-C29*Inputs!B36 -> -435.40981 | D36: =-D29*Inputs!C36 -> -433.491 | E36: =-E29*Inputs!D36 -> -423.17051 | F36: =-F29*Inputs!E36 -> -404.48554 | G36: =-G29*Inputs!F36 -> -377.90225 | H36: =-H29*Inputs!G36 -> -344.30746
A37: Change in NWC | C37: =-Inputs!B37*(C29-B29) -> -327.62597 | D37: =-Inputs!C37*(D29-C29) -> -239.31184 | E37: =-Inputs!D37*(E29-D29) -> -210.06268 | F37: =-Inputs!E37*(F29-E29) -> -172.69539 | G37: =-Inputs!F37*(G29-F29) -> -128.16442 | H37: =-Inputs!G37*(H29-G29) -> -77.898732
A38: Unlevered FCF | C38: =C35+C32+C36+C37 -> 323.23067 | D38: =D35+D32+D36+D37 -> 489.18337 | E38: =E35+E32+E36+E37 -> 593.50709 | F38: =F35+F32+F36+F37 -> 700.77356 | G38: =G35+G32+G36+G37 -> 807.37652 | H38: =H35+H32+H36+H37 -> 909.35229
A39: Enterprise value | B39: =SUMPRODUCT($C$38:$H$38,(1+$G$6)^(-DCF!$B$6:$G$6))-$C$38*Inputs!$B$20*(1+$G$6)^(-DCF!$B$6)+IF(Inputs!$B$21=1,$H$35*(1+$H$6)*(1-$H$6/Inputs!$B$22),$H$38*(1+$H$6))/($G$6-$H$6)/(1+$G$6)^(6-Inputs!$B$19) -> 17300.017
A40: Value per share (NOK) | B40: =(B39-Inputs!$B$8-Inputs!$B$9)/Inputs!$B$7/Inputs!$B$6 -> 293.47403
A42: Bull case (EURm) | B42: =Forecast!B4 -> 2025A | C42: 2026E | D42: 2027E | E42: 2028E | F42: 2029E | G42: 2030E | H42: 2031E
A43: Revenue growth | C43: =Inputs!B33+$C$7 -> 0.1363 | D43: =Inputs!C33+$C$7 -> 0.0961 | E43: =Inputs!D33+$C$7 -> 0.082075 | F43: =Inputs!E33+$C$7 -> 0.06805 | G43: =Inputs!F33+$C$7 -> 0.054025 | H43: =Inputs!G33+$C$7 -> 0.04
A44: Revenue | B44: =Forecast!B6 -> 5688.7 | C44: =B44*(1+C43) -> 6464.0698 | D44: =C44*(1+D43) -> 7085.2669 | E44: =D44*(1+E43) -> 7666.7902 | F44: =E44*(1+F43) -> 8188.5153 | G44: =F44*(1+G43) -> 8630.8998 | H44: =G44*(1+H43) -> 8976.1358
A45: EBITDA margin | C45: =Inputs!B34+$D$7 -> 0.2227762 | D45: =Inputs!C34+$D$7 -> 0.22147322 | E45: =Inputs!D34+$D$7 -> 0.22017024 | F45: =Inputs!E34+$D$7 -> 0.21886726 | G45: =Inputs!F34+$D$7 -> 0.21756428 | H45: =Inputs!G34+$D$7 -> 0.2162613
A46: EBITDA | C46: =C44*C45 -> 1440.0409 | D46: =D44*D45 -> 1569.1969 | E46: =E44*E45 -> 1687.999 | F46: =F44*F45 -> 1792.1979 | G46: =G44*G45 -> 1877.7755 | H46: =H44*H45 -> 1941.1908
...

Sheet Peers
A1: Peer multiples
A2: LTM figures where the quarters are reported (else the last fiscal year); EV = market cap today + latest net debt, same lease basis as the target company; P/E on trailing twelve-month EPS.
A4: Company | B4: Ticker | C4: Group | D4: Market cap (EURm) | E4: EV (EURm) | F4: Rev. growth | G4: EBITDA margin | H4: EV/Sales | I4: EV/EBITDA | J4: EV/EBIT | K4: P/E | L4: P/E (NTM) | M4: EV/Sales (NTM) | N4: EV/EBITDA (NTM*) | O4: P/E (FY0) | P4: P/E (FY1) | Q4: Growth FY1 | R4: EPS growth | S4: PEG | T4: FCF yield | U4: Div. yield
A5: SalMar | B5: SALM.OL | C5: Salmon farming | D5: 6742.2522 | E5: 8706.3679 | F5: 0.038946728 | G5: 0.20198947 | H5: 3.1359972 | I5: 15.525548 | J5: 20.729158 | K5: 32.986534 | L5: 16.242433 | M5: 2.7082946 | N5: 13.408098 | O5: 20.425262 | P5: 15.093148 | Q5: 0.11143474 | R5: 0.35328049 | S5: 0.45976026 | T5: 0.0099240206 | U5: 0.018552876
A6: Lerøy Seafood | B6: LSG.OL | C6: Salmon farming | D6: 2274.0987 | E6: 3044.9809 | F6: 0.1040417 | G6: 0.10473221 | H6: 0.9830169 | I6: 9.3860032 | J6: 21.508583 | K6: 34.77311 | L6: 11.365418 | M6: 0.91515717 | N6: 8.7380676 | O6: 13.614843 | P6: 10.707613 | Q6: 0.095736999 | R6: 0.2715105 | S6: 0.41859959 | T6: 0.10209594 | U6: 0.06041566
A7: Bakkafrost | B7: BAKKA.OL | C7: Salmon farming | D7: 2354.9247 | E7: 2895.1593 | F7: -0.044524341 | G7: 0.24455029 | H7: 2.8991333 | I7: 11.854958 | J7: 18.349478 | K7: 21.638191 | L7: 14.121894 | M7: 2.3353735 | N7: 9.5496656 | O7: 18.492091 | P7: 12.981185 | Q7: 0.2348608 | R7: 0.42453032 | S7: 0.33264747 | T7: -0.012988578 | U7: 0.011751045
A8: Grieg Seafood | B8: GSF.OL | C8: Salmon farming | D8: 261.66467 | E8: 387.42705 | F8: 0.11355675 | G8: 0.10676 | H8: 1.1363001 | I8: 10.6435 | J8: 13.757959 | L8: 10.916825 | M8: 1.0239387 | N8: 9.5910328 | O8: 24.44524 | P8: 9.0537634 | Q8: 0.10040582 | R8: 1.7000087 | S8: 0.064216292 | T8: -0.21884282
A10: Average | F10: =IFERROR(AVERAGE(F5:F8),"") -> 0.053005211 | G10: =IFERROR(AVERAGE(G5:G8),"") -> 0.16450799 | H10: =IFERROR(AVERAGE(H5:H8),"") -> 2.0386119 | I10: =IFERROR(AVERAGE(I5:I8),"") -> 11.852502 | J10: =IFERROR(AVERAGE(J5:J8),"") -> 18.586295 | K10: =IFERROR(AVERAGE(K5:K8),"") -> 29.799278 | L10: =IFERROR(AVERAGE(L5:L8),"") -> 13.161643 | M10: =IFERROR(AVERAGE(M5:M8),"") -> 1.745691 | ... U10: =IFERROR(AVERAGE(U5:U8),"") -> 0.03023986
A11: Median | F11: =IFERROR(MEDIAN(F5:F8),"") -> 0.071494214 | G11: =IFERROR(MEDIAN(G5:G8),"") -> 0.15437473 | H11: =IFERROR(MEDIAN(H5:H8),"") -> 2.0177167 | I11: =IFERROR(MEDIAN(I5:I8),"") -> 11.249229 | J11: =IFERROR(MEDIAN(J5:J8),"") -> 19.539318 | K11: =IFERROR(MEDIAN(K5:K8),"") -> 32.986534 | L11: =IFERROR(MEDIAN(L5:L8),"") -> 12.743656 | M11: =IFERROR(MEDIAN(M5:M8),"") -> 1.6796561 | ... U11: =IFERROR(MEDIAN(U5:U8),"") -> 0.018552876
A12: 25th percentile | F12: =IFERROR(QUARTILE(F5:F8,1),"") -> 0.018078961 | G12: =IFERROR(QUARTILE(G5:G8,1),"") -> 0.10625305 | H12: =IFERROR(QUARTILE(H5:H8,1),"") -> 1.0979793 | I12: =IFERROR(QUARTILE(I5:I8,1),"") -> 10.329126 | J12: =IFERROR(QUARTILE(J5:J8,1),"") -> 17.201599 | K12: =IFERROR(QUARTILE(K5:K8,1),"") -> 27.312362 | L12: =IFERROR(QUARTILE(L5:L8,1),"") -> 11.25327 | M12: =IFERROR(QUARTILE(M5:M8,1),"") -> 0.99674329 | ... U12: =IFERROR(QUARTILE(U5:U8,1),"") -> 0.01515196
A13: 75th percentile | F13: =IFERROR(QUARTILE(F5:F8,3),"") -> 0.10642046 | G13: =IFERROR(QUARTILE(G5:G8,3),"") -> 0.21262967 | H13: =IFERROR(QUARTILE(H5:H8,3),"") -> 2.9583493 | I13: =IFERROR(QUARTILE(I5:I8,3),"") -> 12.772605 | J13: =IFERROR(QUARTILE(J5:J8,3),"") -> 20.924014 | K13: =IFERROR(QUARTILE(K5:K8,3),"") -> 33.879822 | L13: =IFERROR(QUARTILE(L5:L8,3),"") -> 14.652029 | M13: =IFERROR(QUARTILE(M5:M8,3),"") -> 2.4286038 | ... U13: =IFERROR(QUARTILE(U5:U8,3),"") -> 0.039484268
A16: Mowi – current multiples and implied value | D16: Multiple | E16: Mowi | F16: Peer median | G16: Implied value/share (NOK) | H16: vs price
A17: Market cap | B17: =(Inputs!$B$5*Inputs!$B$6)*Inputs!$B$7 -> 9426.1487 | D17: EV/Sales | E17: =IF(B19<=0,"n.m.",B18/B19) -> 2.0348358 | F17: =H11 -> 2.0177167 | G17: =IF(B19<=0,"",(H11*B19-Inputs!$B$8-Inputs!$B$9)/Inputs!$B$7/Inputs!$B$6) -> 191.54856 | H17: =IF(G17="","",G17/Inputs!$B$5-1) -> -0.011107083
A18: Enterprise value | B18: =B17+Inputs!$B$8+Inputs!$B$9 -> 12444.649 | D18: EV/EBITDA | E18: =IF(B20<=0,"n.m.",B18/B20) -> 10.3788 | F18: =I11 -> 11.249229 | G18: =IF(B20<=0,"",(I11*B20-Inputs!$B$8-Inputs!$B$9)/Inputs!$B$7/Inputs!$B$6) -> 215.14688 | H18: =IF(G18="","",G18/Inputs!$B$5-1) -> 0.11072214
A19: Revenue (LTM Jun 2026) | B19: 6115.8 | D19: EV/EBIT | E19: =IF(B21<=0,"n.m.",B18/B21) -> 13.162936 | F19: =J11 -> 19.539318 | G19: =IF(B21<=0,"",(J11*B21-Inputs!$B$8-Inputs!$B$9)/Inputs!$B$7/Inputs!$B$6) -> 317.57952 | H19: =IF(G19="","",G19/Inputs!$B$5-1) -> 0.63954323
A20: EBITDA (LTM Jun 2026) | B20: 1199.045 | D20: P/E | E20: =IF(B22<=0,"n.m.",(Inputs!$B$5*Inputs!$B$6)/B22) -> 14.69651 | F20: =K11 -> 32.986534 | G20: =IF(B22<=0,"",K11*B22/Inputs!$B$6) -> 434.76252 | H20: =IF(G20="","",G20/Inputs!$B$5-1) -> 1.2445148
A21: EBIT (LTM Jun 2026) | B21: 945.43106
A22: EPS, trailing 12 months (EUR) | B22: 1.2163822
A24: Income figures: sum of the four quarters to Jun 2026. Net debt: balance sheet 30.06.2026. EPS: Yahoo Finance trailing twelve months, the same basis as the peers' P/E. * EV/EBITDA (NTM) = EV over NTM consensus revenue at the LTM margin (no EBITDA consensus on Yahoo).
A26: EV/EBITDA regression on the peers above (engine OLS with an intercept; coefficients are inputs, the fitted value is live)
A27: Intercept | B27: 11.31724
A28: Coefficient: expected revenue growth | B28: 3.9470842
A29: Coefficient: EBITDA margin | B29: 0
A30: R² | B30: 0.0098234452
A31: Residual standard deviation (x) | B31: 3.2272221
A32: Peers in the regression | B32: 4
A33: Mowi expected revenue growth | B33: 0.07610373
A34: Mowi EBITDA margin (LTM) | B34: =IF(B19>0,B20/B19,0) -> 0.19605694
A35: Fitted EV/EBITDA | B35: =B27+B28*B33+B29*B34 -> 11.617628 | C35: R² 0.01: below 0.15, so the fit is reported but not used as a valuation anchor
A36: Regression-implied value per share (NOK) | B36: =IF(B20<=0,"",(B35*B20-Inputs!$B$8-Inputs!$B$9)/Inputs!$B$7/Inputs!$B$6) -> 224.22402

Sheet Football field
A1: Valuation summary
A2: Ranges feed the football-field chart; DCF range = inner 3x3 of the sensitivity grid.
A4: Method | B4: Low | C4: High | D4: Range
A5: 52-week range | B5: 179.4 | C5: 245.8 | D5: =IFERROR(C5-B5,"") -> 66.4
A6: DCF (WACC ±0.5%, g ±0.25%) | B6: =MIN(DCF!D40:F42) -> 244.5491 | C6: =MAX(DCF!D40:F42) -> 361.35637 | D6: =IFERROR(C6-B6,"") -> 116.80726
A7: EV/EBITDA (peer 25th–75th pct) | B7: =(Peers!I12*Peers!B20-Inputs!$B$8-Inputs!$B$9)/Inputs!$B$7/Inputs!$B$6 -> 192.47606 | C7: =(Peers!I13*Peers!B20-Inputs!$B$8-Inputs!$B$9)/Inputs!$B$7/Inputs!$B$6 -> 252.68202 | D7: =IFERROR(C7-B7,"") -> 60.205966
A8: EV/EBIT (peer 25th–75th pct) | B8: =(Peers!J12*Peers!B21-Inputs!$B$8-Inputs!$B$9)/Inputs!$B$7/Inputs!$B$6 -> 272.16261 | C8: =(Peers!J13*Peers!B21-Inputs!$B$8-Inputs!$B$9)/Inputs!$B$7/Inputs!$B$6 -> 344.48122 | D8: =IFERROR(C8-B8,"") -> 72.318608
A9: P/E (peer 25th–75th pct) | B9: =Peers!K12*Peers!B22/Inputs!$B$6 -> 359.97694 | C9: =Peers!K13*Peers!B22/Inputs!$B$6 -> 446.53605 | D9: =IFERROR(C9-B9,"") -> 86.559116
A11: Current share price (NOK) | B11: =Inputs!$B$5 -> 193.7
A12: Target price (NOK) | B12: =DCF!$B$30 -> 308.5
A13: Rating | B13: =DCF!$B$33 -> BUY

Sheet Checks
A1: Model integrity checks
A2: Every check must read TRUE. A FALSE means an input or formula has been broken.
A4: Check | B4: Result | C4: What it protects against
A5: WACC exceeds terminal growth | B5: =WACC!$B$17>Inputs!$B$11 -> TRUE | C5: A perpetuity needs WACC > g
A6: Enterprise value = PV of FCF + PV of terminal value | B6: =ABS(DCF!B16-(DCF!B10+DCF!B15))<0.01 -> TRUE | C6: Broken bridge formulas
A7: Equity value = EV - net debt - minorities | B7: =ABS(DCF!B19-(DCF!B16-Inputs!$B$8-Inputs!$B$9))<0.01 -> TRUE | C7: Sign errors in the bridge
A8: Sensitivity centre equals the DCF fair value | B8: =ABS(DCF!E41-DCF!B21)<0.01 -> TRUE | C8: Sensitivity grid out of sync with the model
A9: Base scenario reproduces the DCF fair value | B9: =ABS(Scenarios!I6-DCF!B21)<0.01 -> TRUE | C9: Scenario blocks drifting from the forecast
A10: Forecast starts from the last reported revenue | B10: =Forecast!B6=Historicals!E5 -> TRUE | C10: Stale links
A11: Capital structure weights sum to 100% | B11: =ABS(WACC!B15+WACC!B16-1)<0.000001 -> TRUE | C11: WACC weights
A12: Scenario probabilities sum to 100% | B12: =ABS(Scenarios!B8-1)<0.000001 -> TRUE | C12: Probability-weighted value
A13: Share price, shares and FX are positive | B13: =AND(Inputs!$B$5>0,Inputs!$B$7>0,Inputs!$B$6>0) -> TRUE | C13: Missing market data
A14: Terminal value below 85% of enterprise value | B14: =DCF!B24<0.85 -> TRUE | C14: Valuation resting almost entirely on the perpetuity
A15: No error values in Forecast, DCF or Scenarios | B15: =SUMPRODUCT(--ISERROR(Forecast!B5:I20))+SUMPRODUCT(--ISERROR(DCF!B5:G33))+SUMPRODUCT(--ISERROR(Scenarios!B5:J8))=0 -> TRUE | C15: #REF!, #DIV/0! and friends
A17: Overall status | B17: =IF(AND(B5:B15),"ALL OK","CHECK") -> ALL OK
